2018-04-13 17:15:20 [basehttp INFO] "GET / HTTP/1.1" 302 0
2018-04-13 17:15:20 [basehttp INFO] "GET /users/login?next=/ HTTP/1.1" 200 4754
2018-04-13 17:15:20 [basehttp INFO] "GET /static/css/plugins/toastr/toastr.min.css HTTP/1.1" 200 6454
2018-04-13 17:15:20 [basehttp INFO] "GET /static/css/plugins/sweetalert/sweetalert.css HTTP/1.1" 200 18130
2018-04-13 17:15:20 [basehttp INFO] "GET /static/css/font-awesome.min.css HTTP/1.1" 200 31000
2018-04-13 17:15:20 [basehttp INFO] "GET /static/css/animate.css HTTP/1.1" 200 65564
2018-04-13 17:15:20 [basehttp INFO] "GET /static/css/bootstrap.min.css HTTP/1.1" 200 114011
2018-04-13 17:15:20 [basehttp INFO] "GET /static/css/style.css HTTP/1.1" 200 173145
2018-04-13 17:15:20 [basehttp INFO] "GET /static/css/plugins/datatables/datatables.min.css HTTP/1.1" 200 16774
2018-04-13 17:15:20 [basehttp INFO] "GET /static/css/jumpserver.css HTTP/1.1" 200 7091
2018-04-13 17:15:20 [basehttp INFO] "GET /static/css/plugins/vaildator/jquery.validator.css HTTP/1.1" 200 3526
2018-04-13 17:15:20 [basehttp INFO] "GET /static/css/navi.css HTTP/1.1" 200 2174
2018-04-13 17:15:20 [basehttp INFO] "GET /static/js/plugins/sweetalert/sweetalert.min.js HTTP/1.1" 200 16141
2018-04-13 17:15:20 [basehttp INFO] "GET /static/js/jquery-2.1.1.js HTTP/1.1" 200 84251
2018-04-13 17:15:20 [basehttp INFO] "GET /static/js/bootstrap.min.js HTTP/1.1" 200 34653
2018-04-13 17:15:20 [basehttp INFO] "GET /static/js/jumpserver.js HTTP/1.1" 200 18568
2018-04-13 17:15:20 [basehttp INFO] "GET /static/img/logo.png HTTP/1.1" 200 16275
2018-04-13 17:15:20 [basehttp INFO] "GET /static/js/plugins/datatables/datatables.min.js HTTP/1.1" 200 1287123
2018-04-13 17:15:20 [basehttp INFO] "GET /captcha/image/d66c7fbe2f6e9717f2e08fce21f4db7841df3124/ HTTP/1.1" 200 4401
2018-04-13 17:15:21 [basehttp INFO] "GET /static/img/facio.ico HTTP/1.1" 200 1744
2018-04-13 17:15:30 [basehttp INFO] "POST /users/login?next=/ HTTP/1.1" 200 4983
2018-04-13 17:15:30 [basehttp INFO] "GET /captcha/image/9fcbbeb6ba5679636c2cbd44c5bbea02c082b7a4/ HTTP/1.1" 200 3960
2018-04-13 17:16:03 [basehttp INFO] "POST /users/login?next=/ HTTP/1.1" 200 4983
2018-04-13 17:16:03 [basehttp INFO] "GET /captcha/image/634b3a044231de22064a804703f456634c39923a/ HTTP/1.1" 200 3785
2018-04-13 17:16:11 [basehttp INFO] "POST /users/login?next=/ HTTP/1.1" 200 4983
2018-04-13 17:16:12 [basehttp INFO] "GET /captcha/image/415ae324132d0b25510bbbc5721373dceff2636c/ HTTP/1.1" 200 4092
2018-04-13 17:23:05 [basehttp INFO] "POST /users/login?next=/ HTTP/1.1" 200 4910
2018-04-13 17:23:05 [basehttp INFO] "GET /captcha/image/923f8a34b62063279131fc009f8502e8695504d5/ HTTP/1.1" 200 4480
2018-04-13 17:42:19 [basehttp INFO] "GET / HTTP/1.1" 302 0
2018-04-13 17:42:19 [basehttp INFO] "GET /users/login?next=/ HTTP/1.1" 200 4754
2018-04-13 17:42:19 [basehttp INFO] "GET /static/css/animate.css HTTP/1.1" 200 65564
2018-04-13 17:42:19 [basehttp INFO] "GET /static/css/bootstrap.min.css HTTP/1.1" 200 114011
2018-04-13 17:42:19 [basehttp INFO] "GET /static/css/font-awesome.min.css HTTP/1.1" 200 31000
2018-04-13 17:42:19 [basehttp INFO] "GET /static/css/plugins/sweetalert/sweetalert.css HTTP/1.1" 200 18130
2018-04-13 17:42:19 [basehttp INFO] "GET /static/css/plugins/toastr/toastr.min.css HTTP/1.1" 200 6454
2018-04-13 17:42:19 [basehttp INFO] "GET /static/css/style.css HTTP/1.1" 200 173145
2018-04-13 17:42:19 [basehttp INFO] "GET /static/css/plugins/vaildator/jquery.validator.css HTTP/1.1" 200 3526
2018-04-13 17:42:19 [basehttp INFO] "GET /static/css/plugins/datatables/datatables.min.css HTTP/1.1" 200 16774
2018-04-13 17:42:19 [basehttp INFO] "GET /static/css/navi.css HTTP/1.1" 200 2174
2018-04-13 17:42:19 [basehttp INFO] "GET /static/css/jumpserver.css HTTP/1.1" 200 7091
2018-04-13 17:42:19 [basehttp INFO] "GET /static/js/jquery-2.1.1.js HTTP/1.1" 200 84251
2018-04-13 17:42:19 [basehttp INFO] "GET /static/js/plugins/sweetalert/sweetalert.min.js HTTP/1.1" 200 16141
2018-04-13 17:42:19 [basehttp INFO] "GET /static/js/bootstrap.min.js HTTP/1.1" 200 34653
2018-04-13 17:42:20 [basehttp INFO] "GET /static/js/jumpserver.js HTTP/1.1" 200 18568
2018-04-13 17:42:20 [basehttp INFO] "GET /static/img/logo.png HTTP/1.1" 200 16275
2018-04-13 17:42:20 [basehttp INFO] "GET /static/js/plugins/datatables/datatables.min.js HTTP/1.1" 200 1287123
2018-04-13 17:42:20 [basehttp INFO] "GET /captcha/image/8c9f53b73487122b62a6776839746767afd53b97/ HTTP/1.1" 200 3973
2018-04-13 17:42:20 [basehttp INFO] "GET /static/img/facio.ico HTTP/1.1" 200 1744
2018-04-13 17:42:26 [exception ERROR] Internal Server Error: /users/login
Traceback (most recent call last):
  File "/Users/xuexianmao/venu/jum3/lib/python3.6/site-packages/kombu/utils/functional.py", line 36, in __call__
    return self.__value__
AttributeError: 'ChannelPromise' object has no attribute '__value__'

During handling of the above exception, another exception occurred:

Traceback (most recent call last):
  File "/Users/xuexianmao/venu/jum3/lib/python3.6/site-packages/kombu/connection.py", line 494, in _ensured
    return fun(*args, **kwargs)
  File "/Users/xuexianmao/venu/jum3/lib/python3.6/site-packages/kombu/messaging.py", line 187, in _publish
    channel = self.channel
  File "/Users/xuexianmao/venu/jum3/lib/python3.6/site-packages/kombu/messaging.py", line 209, in _get_channel
    channel = self._channel = channel()
  File "/Users/xuexianmao/venu/jum3/lib/python3.6/site-packages/kombu/utils/functional.py", line 38, in __call__
    value = self.__value__ = self.__contract__()
  File "/Users/xuexianmao/venu/jum3/lib/python3.6/site-packages/kombu/messaging.py", line 224, in <lambda>
    channel = ChannelPromise(lambda: connection.default_channel)
  File "/Users/xuexianmao/venu/jum3/lib/python3.6/site-packages/kombu/connection.py", line 819, in default_channel
    self.connection
  File "/Users/xuexianmao/venu/jum3/lib/python3.6/site-packages/kombu/connection.py", line 802, in connection
    self._connection = self._establish_connection()
  File "/Users/xuexianmao/venu/jum3/lib/python3.6/site-packages/kombu/connection.py", line 757, in _establish_connection
    conn = self.transport.establish_connection()
  File "/Users/xuexianmao/venu/jum3/lib/python3.6/site-packages/kombu/transport/pyamqp.py", line 130, in establish_connection
    conn.connect()
  File "/Users/xuexianmao/venu/jum3/lib/python3.6/site-packages/amqp/connection.py", line 294, in connect
    self.transport.connect()
  File "/Users/xuexianmao/venu/jum3/lib/python3.6/site-packages/amqp/transport.py", line 120, in connect
    self._connect(self.host, self.port, self.connect_timeout)
  File "/Users/xuexianmao/venu/jum3/lib/python3.6/site-packages/amqp/transport.py", line 161, in _connect
    self.sock.connect(sa)
ConnectionRefusedError: [Errno 61] Connection refused

During handling of the above exception, another exception occurred:

Traceback (most recent call last):
  File "/Users/xuexianmao/venu/jum3/lib/python3.6/site-packages/kombu/connection.py", line 414, in _reraise_as_library_errors
    yield
  File "/Users/xuexianmao/venu/jum3/lib/python3.6/site-packages/kombu/connection.py", line 515, in _ensured
    reraise_as_library_errors=False,
  File "/Users/xuexianmao/venu/jum3/lib/python3.6/site-packages/kombu/connection.py", line 405, in ensure_connection
    callback)
  File "/Users/xuexianmao/venu/jum3/lib/python3.6/site-packages/kombu/utils/functional.py", line 333, in retry_over_time
    return fun(*args, **kwargs)
  File "/Users/xuexianmao/venu/jum3/lib/python3.6/site-packages/kombu/connection.py", line 261, in connect
    return self.connection
  File "/Users/xuexianmao/venu/jum3/lib/python3.6/site-packages/kombu/connection.py", line 802, in connection
    self._connection = self._establish_connection()
  File "/Users/xuexianmao/venu/jum3/lib/python3.6/site-packages/kombu/connection.py", line 757, in _establish_connection
    conn = self.transport.establish_connection()
  File "/Users/xuexianmao/venu/jum3/lib/python3.6/site-packages/kombu/transport/pyamqp.py", line 130, in establish_connection
    conn.connect()
  File "/Users/xuexianmao/venu/jum3/lib/python3.6/site-packages/amqp/connection.py", line 294, in connect
    self.transport.connect()
  File "/Users/xuexianmao/venu/jum3/lib/python3.6/site-packages/amqp/transport.py", line 120, in connect
    self._connect(self.host, self.port, self.connect_timeout)
  File "/Users/xuexianmao/venu/jum3/lib/python3.6/site-packages/amqp/transport.py", line 161, in _connect
    self.sock.connect(sa)
ConnectionRefusedError: [Errno 61] Connection refused

During handling of the above exception, another exception occurred:

Traceback (most recent call last):
  File "/Users/xuexianmao/venu/jum3/lib/python3.6/site-packages/django/core/handlers/exception.py", line 41, in inner
    response = get_response(request)
  File "/Users/xuexianmao/venu/jum3/lib/python3.6/site-packages/django/core/handlers/base.py", line 187, in _get_response
    response = self.process_exception_by_middleware(e, request)
  File "/Users/xuexianmao/venu/jum3/lib/python3.6/site-packages/django/core/handlers/base.py", line 185, in _get_response
    response = wrapped_callback(request, *callback_args, **callback_kwargs)
  File "/usr/local/Cellar/python3/3.6.3/Frameworks/Python.framework/Versions/3.6/lib/python3.6/contextlib.py", line 52, in inner
    return func(*args, **kwds)
  File "/Users/xuexianmao/venu/jum3/lib/python3.6/site-packages/django/views/generic/base.py", line 68, in view
    return self.dispatch(request, *args, **kwargs)
  File "/Users/xuexianmao/venu/jum3/lib/python3.6/site-packages/django/utils/decorators.py", line 67, in _wrapper
    return bound_func(*args, **kwargs)
  File "/Users/xuexianmao/venu/jum3/lib/python3.6/site-packages/django/views/decorators/debug.py", line 76, in sensitive_post_parameters_wrapper
    return view(request, *args, **kwargs)
  File "/Users/xuexianmao/venu/jum3/lib/python3.6/site-packages/django/utils/decorators.py", line 63, in bound_func
    return func.__get__(self, type(self))(*args2, **kwargs2)
  File "/Users/xuexianmao/venu/jum3/lib/python3.6/site-packages/django/utils/decorators.py", line 67, in _wrapper
    return bound_func(*args, **kwargs)
  File "/Users/xuexianmao/venu/jum3/lib/python3.6/site-packages/django/utils/decorators.py", line 149, in _wrapped_view
    response = view_func(request, *args, **kwargs)
  File "/Users/xuexianmao/venu/jum3/lib/python3.6/site-packages/django/utils/decorators.py", line 63, in bound_func
    return func.__get__(self, type(self))(*args2, **kwargs2)
  File "/Users/xuexianmao/venu/jum3/lib/python3.6/site-packages/django/utils/decorators.py", line 67, in _wrapper
    return bound_func(*args, **kwargs)
  File "/Users/xuexianmao/venu/jum3/lib/python3.6/site-packages/django/views/decorators/cache.py", line 57, in _wrapped_view_func
    response = view_func(request, *args, **kwargs)
  File "/Users/xuexianmao/venu/jum3/lib/python3.6/site-packages/django/utils/decorators.py", line 63, in bound_func
    return func.__get__(self, type(self))(*args2, **kwargs2)
  File "/Users/xuexianmao/venu/jum3/lib/python3.6/site-packages/django/views/generic/base.py", line 88, in dispatch
    return handler(request, *args, **kwargs)
  File "/Users/xuexianmao/venu/jum3/lib/python3.6/site-packages/django/views/generic/edit.py", line 183, in post
    return self.form_valid(form)
  File "/Users/xuexianmao/PycharmProjects/diting/apps/users/views/login.py", line 68, in form_valid
    ip=login_ip, user_agent=user_agent
  File "/Users/xuexianmao/venu/jum3/lib/python3.6/site-packages/celery/app/task.py", line 413, in delay
    return self.apply_async(args, kwargs)
  File "/Users/xuexianmao/venu/jum3/lib/python3.6/site-packages/celery/app/task.py", line 536, in apply_async
    **options
  File "/Users/xuexianmao/venu/jum3/lib/python3.6/site-packages/celery/app/base.py", line 737, in send_task
    amqp.send_task_message(P, name, message, **options)
  File "/Users/xuexianmao/venu/jum3/lib/python3.6/site-packages/celery/app/amqp.py", line 554, in send_task_message
    **properties
  File "/Users/xuexianmao/venu/jum3/lib/python3.6/site-packages/kombu/messaging.py", line 181, in publish
    exchange_name, declare,
  File "/Users/xuexianmao/venu/jum3/lib/python3.6/site-packages/kombu/connection.py", line 527, in _ensured
    errback and errback(exc, 0)
  File "/usr/local/Cellar/python3/3.6.3/Frameworks/Python.framework/Versions/3.6/lib/python3.6/contextlib.py", line 99, in __exit__
    self.gen.throw(type, value, traceback)
  File "/Users/xuexianmao/venu/jum3/lib/python3.6/site-packages/kombu/connection.py", line 419, in _reraise_as_library_errors
    sys.exc_info()[2])
  File "/Users/xuexianmao/venu/jum3/lib/python3.6/site-packages/vine/five.py", line 178, in reraise
    raise value.with_traceback(tb)
  File "/Users/xuexianmao/venu/jum3/lib/python3.6/site-packages/kombu/connection.py", line 414, in _reraise_as_library_errors
    yield
  File "/Users/xuexianmao/venu/jum3/lib/python3.6/site-packages/kombu/connection.py", line 515, in _ensured
    reraise_as_library_errors=False,
  File "/Users/xuexianmao/venu/jum3/lib/python3.6/site-packages/kombu/connection.py", line 405, in ensure_connection
    callback)
  File "/Users/xuexianmao/venu/jum3/lib/python3.6/site-packages/kombu/utils/functional.py", line 333, in retry_over_time
    return fun(*args, **kwargs)
  File "/Users/xuexianmao/venu/jum3/lib/python3.6/site-packages/kombu/connection.py", line 261, in connect
    return self.connection
  File "/Users/xuexianmao/venu/jum3/lib/python3.6/site-packages/kombu/connection.py", line 802, in connection
    self._connection = self._establish_connection()
  File "/Users/xuexianmao/venu/jum3/lib/python3.6/site-packages/kombu/connection.py", line 757, in _establish_connection
    conn = self.transport.establish_connection()
  File "/Users/xuexianmao/venu/jum3/lib/python3.6/site-packages/kombu/transport/pyamqp.py", line 130, in establish_connection
    conn.connect()
  File "/Users/xuexianmao/venu/jum3/lib/python3.6/site-packages/amqp/connection.py", line 294, in connect
    self.transport.connect()
  File "/Users/xuexianmao/venu/jum3/lib/python3.6/site-packages/amqp/transport.py", line 120, in connect
    self._connect(self.host, self.port, self.connect_timeout)
  File "/Users/xuexianmao/venu/jum3/lib/python3.6/site-packages/amqp/transport.py", line 161, in _connect
    self.sock.connect(sa)
kombu.exceptions.OperationalError: [Errno 61] Connection refused
2018-04-13 17:42:26 [basehttp ERROR] "POST /users/login?next=/ HTTP/1.1" 500 365409
2018-04-13 17:42:27 [base WARNING] Not Found: /favicon.ico
2018-04-13 17:42:27 [basehttp WARNING] "GET /favicon.ico HTTP/1.1" 404 3327
2018-04-13 17:42:56 [basehttp WARNING] "POST /users/login?next=/ HTTP/1.1" 403 2497
2018-04-13 17:43:00 [basehttp INFO] "GET / HTTP/1.1" 302 0
2018-04-13 17:43:00 [basehttp INFO] "GET /users/login?next=/ HTTP/1.1" 200 4754
2018-04-13 17:43:00 [basehttp INFO] "GET /captcha/image/7b765b0026af8b4e6cdebf29eaede476fa675a73/ HTTP/1.1" 200 4138
2018-04-13 17:43:00 [basehttp INFO] "GET /static/img/facio.ico HTTP/1.1" 200 1744
2018-04-13 17:43:08 [exception ERROR] Internal Server Error: /users/login
Traceback (most recent call last):
  File "/Users/xuexianmao/venu/jum3/lib/python3.6/site-packages/kombu/utils/functional.py", line 36, in __call__
    return self.__value__
AttributeError: 'ChannelPromise' object has no attribute '__value__'

During handling of the above exception, another exception occurred:

Traceback (most recent call last):
  File "/Users/xuexianmao/venu/jum3/lib/python3.6/site-packages/kombu/connection.py", line 494, in _ensured
    return fun(*args, **kwargs)
  File "/Users/xuexianmao/venu/jum3/lib/python3.6/site-packages/kombu/messaging.py", line 187, in _publish
    channel = self.channel
  File "/Users/xuexianmao/venu/jum3/lib/python3.6/site-packages/kombu/messaging.py", line 209, in _get_channel
    channel = self._channel = channel()
  File "/Users/xuexianmao/venu/jum3/lib/python3.6/site-packages/kombu/utils/functional.py", line 38, in __call__
    value = self.__value__ = self.__contract__()
  File "/Users/xuexianmao/venu/jum3/lib/python3.6/site-packages/kombu/messaging.py", line 224, in <lambda>
    channel = ChannelPromise(lambda: connection.default_channel)
  File "/Users/xuexianmao/venu/jum3/lib/python3.6/site-packages/kombu/connection.py", line 819, in default_channel
    self.connection
  File "/Users/xuexianmao/venu/jum3/lib/python3.6/site-packages/kombu/connection.py", line 802, in connection
    self._connection = self._establish_connection()
  File "/Users/xuexianmao/venu/jum3/lib/python3.6/site-packages/kombu/connection.py", line 757, in _establish_connection
    conn = self.transport.establish_connection()
  File "/Users/xuexianmao/venu/jum3/lib/python3.6/site-packages/kombu/transport/pyamqp.py", line 130, in establish_connection
    conn.connect()
  File "/Users/xuexianmao/venu/jum3/lib/python3.6/site-packages/amqp/connection.py", line 294, in connect
    self.transport.connect()
  File "/Users/xuexianmao/venu/jum3/lib/python3.6/site-packages/amqp/transport.py", line 120, in connect
    self._connect(self.host, self.port, self.connect_timeout)
  File "/Users/xuexianmao/venu/jum3/lib/python3.6/site-packages/amqp/transport.py", line 161, in _connect
    self.sock.connect(sa)
ConnectionRefusedError: [Errno 61] Connection refused

During handling of the above exception, another exception occurred:

Traceback (most recent call last):
  File "/Users/xuexianmao/venu/jum3/lib/python3.6/site-packages/kombu/connection.py", line 414, in _reraise_as_library_errors
    yield
  File "/Users/xuexianmao/venu/jum3/lib/python3.6/site-packages/kombu/connection.py", line 515, in _ensured
    reraise_as_library_errors=False,
  File "/Users/xuexianmao/venu/jum3/lib/python3.6/site-packages/kombu/connection.py", line 405, in ensure_connection
    callback)
  File "/Users/xuexianmao/venu/jum3/lib/python3.6/site-packages/kombu/utils/functional.py", line 333, in retry_over_time
    return fun(*args, **kwargs)
  File "/Users/xuexianmao/venu/jum3/lib/python3.6/site-packages/kombu/connection.py", line 261, in connect
    return self.connection
  File "/Users/xuexianmao/venu/jum3/lib/python3.6/site-packages/kombu/connection.py", line 802, in connection
    self._connection = self._establish_connection()
  File "/Users/xuexianmao/venu/jum3/lib/python3.6/site-packages/kombu/connection.py", line 757, in _establish_connection
    conn = self.transport.establish_connection()
  File "/Users/xuexianmao/venu/jum3/lib/python3.6/site-packages/kombu/transport/pyamqp.py", line 130, in establish_connection
    conn.connect()
  File "/Users/xuexianmao/venu/jum3/lib/python3.6/site-packages/amqp/connection.py", line 294, in connect
    self.transport.connect()
  File "/Users/xuexianmao/venu/jum3/lib/python3.6/site-packages/amqp/transport.py", line 120, in connect
    self._connect(self.host, self.port, self.connect_timeout)
  File "/Users/xuexianmao/venu/jum3/lib/python3.6/site-packages/amqp/transport.py", line 161, in _connect
    self.sock.connect(sa)
ConnectionRefusedError: [Errno 61] Connection refused

During handling of the above exception, another exception occurred:

Traceback (most recent call last):
  File "/Users/xuexianmao/venu/jum3/lib/python3.6/site-packages/django/core/handlers/exception.py", line 41, in inner
    response = get_response(request)
  File "/Users/xuexianmao/venu/jum3/lib/python3.6/site-packages/django/core/handlers/base.py", line 187, in _get_response
    response = self.process_exception_by_middleware(e, request)
  File "/Users/xuexianmao/venu/jum3/lib/python3.6/site-packages/django/core/handlers/base.py", line 185, in _get_response
    response = wrapped_callback(request, *callback_args, **callback_kwargs)
  File "/usr/local/Cellar/python3/3.6.3/Frameworks/Python.framework/Versions/3.6/lib/python3.6/contextlib.py", line 52, in inner
    return func(*args, **kwds)
  File "/Users/xuexianmao/venu/jum3/lib/python3.6/site-packages/django/views/generic/base.py", line 68, in view
    return self.dispatch(request, *args, **kwargs)
  File "/Users/xuexianmao/venu/jum3/lib/python3.6/site-packages/django/utils/decorators.py", line 67, in _wrapper
    return bound_func(*args, **kwargs)
  File "/Users/xuexianmao/venu/jum3/lib/python3.6/site-packages/django/views/decorators/debug.py", line 76, in sensitive_post_parameters_wrapper
    return view(request, *args, **kwargs)
  File "/Users/xuexianmao/venu/jum3/lib/python3.6/site-packages/django/utils/decorators.py", line 63, in bound_func
    return func.__get__(self, type(self))(*args2, **kwargs2)
  File "/Users/xuexianmao/venu/jum3/lib/python3.6/site-packages/django/utils/decorators.py", line 67, in _wrapper
    return bound_func(*args, **kwargs)
  File "/Users/xuexianmao/venu/jum3/lib/python3.6/site-packages/django/utils/decorators.py", line 149, in _wrapped_view
    response = view_func(request, *args, **kwargs)
  File "/Users/xuexianmao/venu/jum3/lib/python3.6/site-packages/django/utils/decorators.py", line 63, in bound_func
    return func.__get__(self, type(self))(*args2, **kwargs2)
  File "/Users/xuexianmao/venu/jum3/lib/python3.6/site-packages/django/utils/decorators.py", line 67, in _wrapper
    return bound_func(*args, **kwargs)
  File "/Users/xuexianmao/venu/jum3/lib/python3.6/site-packages/django/views/decorators/cache.py", line 57, in _wrapped_view_func
    response = view_func(request, *args, **kwargs)
  File "/Users/xuexianmao/venu/jum3/lib/python3.6/site-packages/django/utils/decorators.py", line 63, in bound_func
    return func.__get__(self, type(self))(*args2, **kwargs2)
  File "/Users/xuexianmao/venu/jum3/lib/python3.6/site-packages/django/views/generic/base.py", line 88, in dispatch
    return handler(request, *args, **kwargs)
  File "/Users/xuexianmao/venu/jum3/lib/python3.6/site-packages/django/views/generic/edit.py", line 183, in post
    return self.form_valid(form)
  File "/Users/xuexianmao/PycharmProjects/diting/apps/users/views/login.py", line 68, in form_valid
    ip=login_ip, user_agent=user_agent
  File "/Users/xuexianmao/venu/jum3/lib/python3.6/site-packages/celery/app/task.py", line 413, in delay
    return self.apply_async(args, kwargs)
  File "/Users/xuexianmao/venu/jum3/lib/python3.6/site-packages/celery/app/task.py", line 536, in apply_async
    **options
  File "/Users/xuexianmao/venu/jum3/lib/python3.6/site-packages/celery/app/base.py", line 737, in send_task
    amqp.send_task_message(P, name, message, **options)
  File "/Users/xuexianmao/venu/jum3/lib/python3.6/site-packages/celery/app/amqp.py", line 554, in send_task_message
    **properties
  File "/Users/xuexianmao/venu/jum3/lib/python3.6/site-packages/kombu/messaging.py", line 181, in publish
    exchange_name, declare,
  File "/Users/xuexianmao/venu/jum3/lib/python3.6/site-packages/kombu/connection.py", line 527, in _ensured
    errback and errback(exc, 0)
  File "/usr/local/Cellar/python3/3.6.3/Frameworks/Python.framework/Versions/3.6/lib/python3.6/contextlib.py", line 99, in __exit__
    self.gen.throw(type, value, traceback)
  File "/Users/xuexianmao/venu/jum3/lib/python3.6/site-packages/kombu/connection.py", line 419, in _reraise_as_library_errors
    sys.exc_info()[2])
  File "/Users/xuexianmao/venu/jum3/lib/python3.6/site-packages/vine/five.py", line 178, in reraise
    raise value.with_traceback(tb)
  File "/Users/xuexianmao/venu/jum3/lib/python3.6/site-packages/kombu/connection.py", line 414, in _reraise_as_library_errors
    yield
  File "/Users/xuexianmao/venu/jum3/lib/python3.6/site-packages/kombu/connection.py", line 515, in _ensured
    reraise_as_library_errors=False,
  File "/Users/xuexianmao/venu/jum3/lib/python3.6/site-packages/kombu/connection.py", line 405, in ensure_connection
    callback)
  File "/Users/xuexianmao/venu/jum3/lib/python3.6/site-packages/kombu/utils/functional.py", line 333, in retry_over_time
    return fun(*args, **kwargs)
  File "/Users/xuexianmao/venu/jum3/lib/python3.6/site-packages/kombu/connection.py", line 261, in connect
    return self.connection
  File "/Users/xuexianmao/venu/jum3/lib/python3.6/site-packages/kombu/connection.py", line 802, in connection
    self._connection = self._establish_connection()
  File "/Users/xuexianmao/venu/jum3/lib/python3.6/site-packages/kombu/connection.py", line 757, in _establish_connection
    conn = self.transport.establish_connection()
  File "/Users/xuexianmao/venu/jum3/lib/python3.6/site-packages/kombu/transport/pyamqp.py", line 130, in establish_connection
    conn.connect()
  File "/Users/xuexianmao/venu/jum3/lib/python3.6/site-packages/amqp/connection.py", line 294, in connect
    self.transport.connect()
  File "/Users/xuexianmao/venu/jum3/lib/python3.6/site-packages/amqp/transport.py", line 120, in connect
    self._connect(self.host, self.port, self.connect_timeout)
  File "/Users/xuexianmao/venu/jum3/lib/python3.6/site-packages/amqp/transport.py", line 161, in _connect
    self.sock.connect(sa)
kombu.exceptions.OperationalError: [Errno 61] Connection refused
2018-04-13 17:43:08 [basehttp ERROR] "POST /users/login?next=/ HTTP/1.1" 500 365410
2018-04-13 19:36:05 [basehttp INFO] "GET / HTTP/1.1" 302 0
2018-04-13 19:36:05 [basehttp INFO] "GET /users/login?next=/ HTTP/1.1" 200 4754
2018-04-13 19:36:05 [basehttp INFO] "GET /static/css/navi.css HTTP/1.1" 304 0
2018-04-13 19:36:06 [basehttp INFO] "GET /captcha/image/4f83a6e749ac0f9dd387a92d9fa8c50a265eaa9b/ HTTP/1.1" 200 4385
2018-04-13 19:36:12 [exception ERROR] Internal Server Error: /users/login
Traceback (most recent call last):
  File "/Users/xuexianmao/venu/jum3/lib/python3.6/site-packages/kombu/utils/functional.py", line 36, in __call__
    return self.__value__
AttributeError: 'ChannelPromise' object has no attribute '__value__'

During handling of the above exception, another exception occurred:

Traceback (most recent call last):
  File "/Users/xuexianmao/venu/jum3/lib/python3.6/site-packages/kombu/connection.py", line 494, in _ensured
    return fun(*args, **kwargs)
  File "/Users/xuexianmao/venu/jum3/lib/python3.6/site-packages/kombu/messaging.py", line 187, in _publish
    channel = self.channel
  File "/Users/xuexianmao/venu/jum3/lib/python3.6/site-packages/kombu/messaging.py", line 209, in _get_channel
    channel = self._channel = channel()
  File "/Users/xuexianmao/venu/jum3/lib/python3.6/site-packages/kombu/utils/functional.py", line 38, in __call__
    value = self.__value__ = self.__contract__()
  File "/Users/xuexianmao/venu/jum3/lib/python3.6/site-packages/kombu/messaging.py", line 224, in <lambda>
    channel = ChannelPromise(lambda: connection.default_channel)
  File "/Users/xuexianmao/venu/jum3/lib/python3.6/site-packages/kombu/connection.py", line 819, in default_channel
    self.connection
  File "/Users/xuexianmao/venu/jum3/lib/python3.6/site-packages/kombu/connection.py", line 802, in connection
    self._connection = self._establish_connection()
  File "/Users/xuexianmao/venu/jum3/lib/python3.6/site-packages/kombu/connection.py", line 757, in _establish_connection
    conn = self.transport.establish_connection()
  File "/Users/xuexianmao/venu/jum3/lib/python3.6/site-packages/kombu/transport/pyamqp.py", line 130, in establish_connection
    conn.connect()
  File "/Users/xuexianmao/venu/jum3/lib/python3.6/site-packages/amqp/connection.py", line 294, in connect
    self.transport.connect()
  File "/Users/xuexianmao/venu/jum3/lib/python3.6/site-packages/amqp/transport.py", line 120, in connect
    self._connect(self.host, self.port, self.connect_timeout)
  File "/Users/xuexianmao/venu/jum3/lib/python3.6/site-packages/amqp/transport.py", line 161, in _connect
    self.sock.connect(sa)
ConnectionRefusedError: [Errno 61] Connection refused

During handling of the above exception, another exception occurred:

Traceback (most recent call last):
  File "/Users/xuexianmao/venu/jum3/lib/python3.6/site-packages/kombu/connection.py", line 414, in _reraise_as_library_errors
    yield
  File "/Users/xuexianmao/venu/jum3/lib/python3.6/site-packages/kombu/connection.py", line 515, in _ensured
    reraise_as_library_errors=False,
  File "/Users/xuexianmao/venu/jum3/lib/python3.6/site-packages/kombu/connection.py", line 405, in ensure_connection
    callback)
  File "/Users/xuexianmao/venu/jum3/lib/python3.6/site-packages/kombu/utils/functional.py", line 333, in retry_over_time
    return fun(*args, **kwargs)
  File "/Users/xuexianmao/venu/jum3/lib/python3.6/site-packages/kombu/connection.py", line 261, in connect
    return self.connection
  File "/Users/xuexianmao/venu/jum3/lib/python3.6/site-packages/kombu/connection.py", line 802, in connection
    self._connection = self._establish_connection()
  File "/Users/xuexianmao/venu/jum3/lib/python3.6/site-packages/kombu/connection.py", line 757, in _establish_connection
    conn = self.transport.establish_connection()
  File "/Users/xuexianmao/venu/jum3/lib/python3.6/site-packages/kombu/transport/pyamqp.py", line 130, in establish_connection
    conn.connect()
  File "/Users/xuexianmao/venu/jum3/lib/python3.6/site-packages/amqp/connection.py", line 294, in connect
    self.transport.connect()
  File "/Users/xuexianmao/venu/jum3/lib/python3.6/site-packages/amqp/transport.py", line 120, in connect
    self._connect(self.host, self.port, self.connect_timeout)
  File "/Users/xuexianmao/venu/jum3/lib/python3.6/site-packages/amqp/transport.py", line 161, in _connect
    self.sock.connect(sa)
ConnectionRefusedError: [Errno 61] Connection refused

During handling of the above exception, another exception occurred:

Traceback (most recent call last):
  File "/Users/xuexianmao/venu/jum3/lib/python3.6/site-packages/django/core/handlers/exception.py", line 41, in inner
    response = get_response(request)
  File "/Users/xuexianmao/venu/jum3/lib/python3.6/site-packages/django/core/handlers/base.py", line 187, in _get_response
    response = self.process_exception_by_middleware(e, request)
  File "/Users/xuexianmao/venu/jum3/lib/python3.6/site-packages/django/core/handlers/base.py", line 185, in _get_response
    response = wrapped_callback(request, *callback_args, **callback_kwargs)
  File "/usr/local/Cellar/python3/3.6.3/Frameworks/Python.framework/Versions/3.6/lib/python3.6/contextlib.py", line 52, in inner
    return func(*args, **kwds)
  File "/Users/xuexianmao/venu/jum3/lib/python3.6/site-packages/django/views/generic/base.py", line 68, in view
    return self.dispatch(request, *args, **kwargs)
  File "/Users/xuexianmao/venu/jum3/lib/python3.6/site-packages/django/utils/decorators.py", line 67, in _wrapper
    return bound_func(*args, **kwargs)
  File "/Users/xuexianmao/venu/jum3/lib/python3.6/site-packages/django/views/decorators/debug.py", line 76, in sensitive_post_parameters_wrapper
    return view(request, *args, **kwargs)
  File "/Users/xuexianmao/venu/jum3/lib/python3.6/site-packages/django/utils/decorators.py", line 63, in bound_func
    return func.__get__(self, type(self))(*args2, **kwargs2)
  File "/Users/xuexianmao/venu/jum3/lib/python3.6/site-packages/django/utils/decorators.py", line 67, in _wrapper
    return bound_func(*args, **kwargs)
  File "/Users/xuexianmao/venu/jum3/lib/python3.6/site-packages/django/utils/decorators.py", line 149, in _wrapped_view
    response = view_func(request, *args, **kwargs)
  File "/Users/xuexianmao/venu/jum3/lib/python3.6/site-packages/django/utils/decorators.py", line 63, in bound_func
    return func.__get__(self, type(self))(*args2, **kwargs2)
  File "/Users/xuexianmao/venu/jum3/lib/python3.6/site-packages/django/utils/decorators.py", line 67, in _wrapper
    return bound_func(*args, **kwargs)
  File "/Users/xuexianmao/venu/jum3/lib/python3.6/site-packages/django/views/decorators/cache.py", line 57, in _wrapped_view_func
    response = view_func(request, *args, **kwargs)
  File "/Users/xuexianmao/venu/jum3/lib/python3.6/site-packages/django/utils/decorators.py", line 63, in bound_func
    return func.__get__(self, type(self))(*args2, **kwargs2)
  File "/Users/xuexianmao/venu/jum3/lib/python3.6/site-packages/django/views/generic/base.py", line 88, in dispatch
    return handler(request, *args, **kwargs)
  File "/Users/xuexianmao/venu/jum3/lib/python3.6/site-packages/django/views/generic/edit.py", line 183, in post
    return self.form_valid(form)
  File "/Users/xuexianmao/PycharmProjects/diting/apps/users/views/login.py", line 68, in form_valid
    ip=login_ip, user_agent=user_agent
  File "/Users/xuexianmao/venu/jum3/lib/python3.6/site-packages/celery/app/task.py", line 413, in delay
    return self.apply_async(args, kwargs)
  File "/Users/xuexianmao/venu/jum3/lib/python3.6/site-packages/celery/app/task.py", line 536, in apply_async
    **options
  File "/Users/xuexianmao/venu/jum3/lib/python3.6/site-packages/celery/app/base.py", line 737, in send_task
    amqp.send_task_message(P, name, message, **options)
  File "/Users/xuexianmao/venu/jum3/lib/python3.6/site-packages/celery/app/amqp.py", line 554, in send_task_message
    **properties
  File "/Users/xuexianmao/venu/jum3/lib/python3.6/site-packages/kombu/messaging.py", line 181, in publish
    exchange_name, declare,
  File "/Users/xuexianmao/venu/jum3/lib/python3.6/site-packages/kombu/connection.py", line 527, in _ensured
    errback and errback(exc, 0)
  File "/usr/local/Cellar/python3/3.6.3/Frameworks/Python.framework/Versions/3.6/lib/python3.6/contextlib.py", line 99, in __exit__
    self.gen.throw(type, value, traceback)
  File "/Users/xuexianmao/venu/jum3/lib/python3.6/site-packages/kombu/connection.py", line 419, in _reraise_as_library_errors
    sys.exc_info()[2])
  File "/Users/xuexianmao/venu/jum3/lib/python3.6/site-packages/vine/five.py", line 178, in reraise
    raise value.with_traceback(tb)
  File "/Users/xuexianmao/venu/jum3/lib/python3.6/site-packages/kombu/connection.py", line 414, in _reraise_as_library_errors
    yield
  File "/Users/xuexianmao/venu/jum3/lib/python3.6/site-packages/kombu/connection.py", line 515, in _ensured
    reraise_as_library_errors=False,
  File "/Users/xuexianmao/venu/jum3/lib/python3.6/site-packages/kombu/connection.py", line 405, in ensure_connection
    callback)
  File "/Users/xuexianmao/venu/jum3/lib/python3.6/site-packages/kombu/utils/functional.py", line 333, in retry_over_time
    return fun(*args, **kwargs)
  File "/Users/xuexianmao/venu/jum3/lib/python3.6/site-packages/kombu/connection.py", line 261, in connect
    return self.connection
  File "/Users/xuexianmao/venu/jum3/lib/python3.6/site-packages/kombu/connection.py", line 802, in connection
    self._connection = self._establish_connection()
  File "/Users/xuexianmao/venu/jum3/lib/python3.6/site-packages/kombu/connection.py", line 757, in _establish_connection
    conn = self.transport.establish_connection()
  File "/Users/xuexianmao/venu/jum3/lib/python3.6/site-packages/kombu/transport/pyamqp.py", line 130, in establish_connection
    conn.connect()
  File "/Users/xuexianmao/venu/jum3/lib/python3.6/site-packages/amqp/connection.py", line 294, in connect
    self.transport.connect()
  File "/Users/xuexianmao/venu/jum3/lib/python3.6/site-packages/amqp/transport.py", line 120, in connect
    self._connect(self.host, self.port, self.connect_timeout)
  File "/Users/xuexianmao/venu/jum3/lib/python3.6/site-packages/amqp/transport.py", line 161, in _connect
    self.sock.connect(sa)
kombu.exceptions.OperationalError: [Errno 61] Connection refused
2018-04-13 19:36:12 [basehttp ERROR] "POST /users/login?next=/ HTTP/1.1" 500 365264
2018-04-13 19:36:13 [base WARNING] Not Found: /favicon.ico
2018-04-13 19:36:13 [basehttp WARNING] "GET /favicon.ico HTTP/1.1" 404 3327
2018-04-13 19:42:11 [basehttp WARNING] "POST /users/login?next=/ HTTP/1.1" 403 2497
2018-04-13 19:42:14 [basehttp WARNING] "POST /users/login?next=/ HTTP/1.1" 403 2497
2018-04-13 19:42:16 [basehttp INFO] "GET / HTTP/1.1" 302 0
2018-04-13 19:42:16 [basehttp INFO] "GET /users/login?next=/ HTTP/1.1" 200 4754
2018-04-13 19:42:16 [basehttp INFO] "GET /captcha/image/ef9eaa91e96be1999798cb4f50ee696e5676e8a2/ HTTP/1.1" 200 4018
2018-04-13 19:42:16 [basehttp INFO] "GET /static/img/facio.ico HTTP/1.1" 200 1744
2018-04-13 19:42:24 [exception ERROR] Internal Server Error: /users/login
Traceback (most recent call last):
  File "/Users/xuexianmao/venu/jum3/lib/python3.6/site-packages/kombu/utils/functional.py", line 36, in __call__
    return self.__value__
AttributeError: 'ChannelPromise' object has no attribute '__value__'

During handling of the above exception, another exception occurred:

Traceback (most recent call last):
  File "/Users/xuexianmao/venu/jum3/lib/python3.6/site-packages/kombu/connection.py", line 494, in _ensured
    return fun(*args, **kwargs)
  File "/Users/xuexianmao/venu/jum3/lib/python3.6/site-packages/kombu/messaging.py", line 187, in _publish
    channel = self.channel
  File "/Users/xuexianmao/venu/jum3/lib/python3.6/site-packages/kombu/messaging.py", line 209, in _get_channel
    channel = self._channel = channel()
  File "/Users/xuexianmao/venu/jum3/lib/python3.6/site-packages/kombu/utils/functional.py", line 38, in __call__
    value = self.__value__ = self.__contract__()
  File "/Users/xuexianmao/venu/jum3/lib/python3.6/site-packages/kombu/messaging.py", line 224, in <lambda>
    channel = ChannelPromise(lambda: connection.default_channel)
  File "/Users/xuexianmao/venu/jum3/lib/python3.6/site-packages/kombu/connection.py", line 819, in default_channel
    self.connection
  File "/Users/xuexianmao/venu/jum3/lib/python3.6/site-packages/kombu/connection.py", line 802, in connection
    self._connection = self._establish_connection()
  File "/Users/xuexianmao/venu/jum3/lib/python3.6/site-packages/kombu/connection.py", line 757, in _establish_connection
    conn = self.transport.establish_connection()
  File "/Users/xuexianmao/venu/jum3/lib/python3.6/site-packages/kombu/transport/pyamqp.py", line 130, in establish_connection
    conn.connect()
  File "/Users/xuexianmao/venu/jum3/lib/python3.6/site-packages/amqp/connection.py", line 294, in connect
    self.transport.connect()
  File "/Users/xuexianmao/venu/jum3/lib/python3.6/site-packages/amqp/transport.py", line 120, in connect
    self._connect(self.host, self.port, self.connect_timeout)
  File "/Users/xuexianmao/venu/jum3/lib/python3.6/site-packages/amqp/transport.py", line 161, in _connect
    self.sock.connect(sa)
ConnectionRefusedError: [Errno 61] Connection refused

During handling of the above exception, another exception occurred:

Traceback (most recent call last):
  File "/Users/xuexianmao/venu/jum3/lib/python3.6/site-packages/kombu/connection.py", line 414, in _reraise_as_library_errors
    yield
  File "/Users/xuexianmao/venu/jum3/lib/python3.6/site-packages/kombu/connection.py", line 515, in _ensured
    reraise_as_library_errors=False,
  File "/Users/xuexianmao/venu/jum3/lib/python3.6/site-packages/kombu/connection.py", line 405, in ensure_connection
    callback)
  File "/Users/xuexianmao/venu/jum3/lib/python3.6/site-packages/kombu/utils/functional.py", line 333, in retry_over_time
    return fun(*args, **kwargs)
  File "/Users/xuexianmao/venu/jum3/lib/python3.6/site-packages/kombu/connection.py", line 261, in connect
    return self.connection
  File "/Users/xuexianmao/venu/jum3/lib/python3.6/site-packages/kombu/connection.py", line 802, in connection
    self._connection = self._establish_connection()
  File "/Users/xuexianmao/venu/jum3/lib/python3.6/site-packages/kombu/connection.py", line 757, in _establish_connection
    conn = self.transport.establish_connection()
  File "/Users/xuexianmao/venu/jum3/lib/python3.6/site-packages/kombu/transport/pyamqp.py", line 130, in establish_connection
    conn.connect()
  File "/Users/xuexianmao/venu/jum3/lib/python3.6/site-packages/amqp/connection.py", line 294, in connect
    self.transport.connect()
  File "/Users/xuexianmao/venu/jum3/lib/python3.6/site-packages/amqp/transport.py", line 120, in connect
    self._connect(self.host, self.port, self.connect_timeout)
  File "/Users/xuexianmao/venu/jum3/lib/python3.6/site-packages/amqp/transport.py", line 161, in _connect
    self.sock.connect(sa)
ConnectionRefusedError: [Errno 61] Connection refused

During handling of the above exception, another exception occurred:

Traceback (most recent call last):
  File "/Users/xuexianmao/venu/jum3/lib/python3.6/site-packages/django/core/handlers/exception.py", line 41, in inner
    response = get_response(request)
  File "/Users/xuexianmao/venu/jum3/lib/python3.6/site-packages/django/core/handlers/base.py", line 187, in _get_response
    response = self.process_exception_by_middleware(e, request)
  File "/Users/xuexianmao/venu/jum3/lib/python3.6/site-packages/django/core/handlers/base.py", line 185, in _get_response
    response = wrapped_callback(request, *callback_args, **callback_kwargs)
  File "/usr/local/Cellar/python3/3.6.3/Frameworks/Python.framework/Versions/3.6/lib/python3.6/contextlib.py", line 52, in inner
    return func(*args, **kwds)
  File "/Users/xuexianmao/venu/jum3/lib/python3.6/site-packages/django/views/generic/base.py", line 68, in view
    return self.dispatch(request, *args, **kwargs)
  File "/Users/xuexianmao/venu/jum3/lib/python3.6/site-packages/django/utils/decorators.py", line 67, in _wrapper
    return bound_func(*args, **kwargs)
  File "/Users/xuexianmao/venu/jum3/lib/python3.6/site-packages/django/views/decorators/debug.py", line 76, in sensitive_post_parameters_wrapper
    return view(request, *args, **kwargs)
  File "/Users/xuexianmao/venu/jum3/lib/python3.6/site-packages/django/utils/decorators.py", line 63, in bound_func
    return func.__get__(self, type(self))(*args2, **kwargs2)
  File "/Users/xuexianmao/venu/jum3/lib/python3.6/site-packages/django/utils/decorators.py", line 67, in _wrapper
    return bound_func(*args, **kwargs)
  File "/Users/xuexianmao/venu/jum3/lib/python3.6/site-packages/django/utils/decorators.py", line 149, in _wrapped_view
    response = view_func(request, *args, **kwargs)
  File "/Users/xuexianmao/venu/jum3/lib/python3.6/site-packages/django/utils/decorators.py", line 63, in bound_func
    return func.__get__(self, type(self))(*args2, **kwargs2)
  File "/Users/xuexianmao/venu/jum3/lib/python3.6/site-packages/django/utils/decorators.py", line 67, in _wrapper
    return bound_func(*args, **kwargs)
  File "/Users/xuexianmao/venu/jum3/lib/python3.6/site-packages/django/views/decorators/cache.py", line 57, in _wrapped_view_func
    response = view_func(request, *args, **kwargs)
  File "/Users/xuexianmao/venu/jum3/lib/python3.6/site-packages/django/utils/decorators.py", line 63, in bound_func
    return func.__get__(self, type(self))(*args2, **kwargs2)
  File "/Users/xuexianmao/venu/jum3/lib/python3.6/site-packages/django/views/generic/base.py", line 88, in dispatch
    return handler(request, *args, **kwargs)
  File "/Users/xuexianmao/venu/jum3/lib/python3.6/site-packages/django/views/generic/edit.py", line 183, in post
    return self.form_valid(form)
  File "/Users/xuexianmao/PycharmProjects/diting/apps/users/views/login.py", line 68, in form_valid
    ip=login_ip, user_agent=user_agent
  File "/Users/xuexianmao/venu/jum3/lib/python3.6/site-packages/celery/app/task.py", line 413, in delay
    return self.apply_async(args, kwargs)
  File "/Users/xuexianmao/venu/jum3/lib/python3.6/site-packages/celery/app/task.py", line 536, in apply_async
    **options
  File "/Users/xuexianmao/venu/jum3/lib/python3.6/site-packages/celery/app/base.py", line 737, in send_task
    amqp.send_task_message(P, name, message, **options)
  File "/Users/xuexianmao/venu/jum3/lib/python3.6/site-packages/celery/app/amqp.py", line 554, in send_task_message
    **properties
  File "/Users/xuexianmao/venu/jum3/lib/python3.6/site-packages/kombu/messaging.py", line 181, in publish
    exchange_name, declare,
  File "/Users/xuexianmao/venu/jum3/lib/python3.6/site-packages/kombu/connection.py", line 527, in _ensured
    errback and errback(exc, 0)
  File "/usr/local/Cellar/python3/3.6.3/Frameworks/Python.framework/Versions/3.6/lib/python3.6/contextlib.py", line 99, in __exit__
    self.gen.throw(type, value, traceback)
  File "/Users/xuexianmao/venu/jum3/lib/python3.6/site-packages/kombu/connection.py", line 419, in _reraise_as_library_errors
    sys.exc_info()[2])
  File "/Users/xuexianmao/venu/jum3/lib/python3.6/site-packages/vine/five.py", line 178, in reraise
    raise value.with_traceback(tb)
  File "/Users/xuexianmao/venu/jum3/lib/python3.6/site-packages/kombu/connection.py", line 414, in _reraise_as_library_errors
    yield
  File "/Users/xuexianmao/venu/jum3/lib/python3.6/site-packages/kombu/connection.py", line 515, in _ensured
    reraise_as_library_errors=False,
  File "/Users/xuexianmao/venu/jum3/lib/python3.6/site-packages/kombu/connection.py", line 405, in ensure_connection
    callback)
  File "/Users/xuexianmao/venu/jum3/lib/python3.6/site-packages/kombu/utils/functional.py", line 333, in retry_over_time
    return fun(*args, **kwargs)
  File "/Users/xuexianmao/venu/jum3/lib/python3.6/site-packages/kombu/connection.py", line 261, in connect
    return self.connection
  File "/Users/xuexianmao/venu/jum3/lib/python3.6/site-packages/kombu/connection.py", line 802, in connection
    self._connection = self._establish_connection()
  File "/Users/xuexianmao/venu/jum3/lib/python3.6/site-packages/kombu/connection.py", line 757, in _establish_connection
    conn = self.transport.establish_connection()
  File "/Users/xuexianmao/venu/jum3/lib/python3.6/site-packages/kombu/transport/pyamqp.py", line 130, in establish_connection
    conn.connect()
  File "/Users/xuexianmao/venu/jum3/lib/python3.6/site-packages/amqp/connection.py", line 294, in connect
    self.transport.connect()
  File "/Users/xuexianmao/venu/jum3/lib/python3.6/site-packages/amqp/transport.py", line 120, in connect
    self._connect(self.host, self.port, self.connect_timeout)
  File "/Users/xuexianmao/venu/jum3/lib/python3.6/site-packages/amqp/transport.py", line 161, in _connect
    self.sock.connect(sa)
kombu.exceptions.OperationalError: [Errno 61] Connection refused
2018-04-13 19:42:24 [basehttp ERROR] "POST /users/login?next=/ HTTP/1.1" 500 363586
2018-04-13 19:47:38 [basehttp WARNING] "POST /users/login?next=/ HTTP/1.1" 403 2497
2018-04-13 19:47:41 [basehttp INFO] "GET / HTTP/1.1" 302 0
2018-04-13 19:47:41 [basehttp INFO] "GET /users/login?next=/ HTTP/1.1" 200 4754
2018-04-13 19:47:41 [basehttp INFO] "GET /captcha/image/3577fe8e7828661d1d5af78265e539935cac6cab/ HTTP/1.1" 200 3795
2018-04-13 19:47:41 [basehttp INFO] "GET /static/img/facio.ico HTTP/1.1" 200 1744
2018-04-13 19:47:49 [exception ERROR] Internal Server Error: /users/login
Traceback (most recent call last):
  File "/Users/xuexianmao/venu/jum3/lib/python3.6/site-packages/kombu/utils/functional.py", line 36, in __call__
    return self.__value__
AttributeError: 'ChannelPromise' object has no attribute '__value__'

During handling of the above exception, another exception occurred:

Traceback (most recent call last):
  File "/Users/xuexianmao/venu/jum3/lib/python3.6/site-packages/kombu/connection.py", line 494, in _ensured
    return fun(*args, **kwargs)
  File "/Users/xuexianmao/venu/jum3/lib/python3.6/site-packages/kombu/messaging.py", line 187, in _publish
    channel = self.channel
  File "/Users/xuexianmao/venu/jum3/lib/python3.6/site-packages/kombu/messaging.py", line 209, in _get_channel
    channel = self._channel = channel()
  File "/Users/xuexianmao/venu/jum3/lib/python3.6/site-packages/kombu/utils/functional.py", line 38, in __call__
    value = self.__value__ = self.__contract__()
  File "/Users/xuexianmao/venu/jum3/lib/python3.6/site-packages/kombu/messaging.py", line 224, in <lambda>
    channel = ChannelPromise(lambda: connection.default_channel)
  File "/Users/xuexianmao/venu/jum3/lib/python3.6/site-packages/kombu/connection.py", line 819, in default_channel
    self.connection
  File "/Users/xuexianmao/venu/jum3/lib/python3.6/site-packages/kombu/connection.py", line 802, in connection
    self._connection = self._establish_connection()
  File "/Users/xuexianmao/venu/jum3/lib/python3.6/site-packages/kombu/connection.py", line 757, in _establish_connection
    conn = self.transport.establish_connection()
  File "/Users/xuexianmao/venu/jum3/lib/python3.6/site-packages/kombu/transport/pyamqp.py", line 130, in establish_connection
    conn.connect()
  File "/Users/xuexianmao/venu/jum3/lib/python3.6/site-packages/amqp/connection.py", line 294, in connect
    self.transport.connect()
  File "/Users/xuexianmao/venu/jum3/lib/python3.6/site-packages/amqp/transport.py", line 120, in connect
    self._connect(self.host, self.port, self.connect_timeout)
  File "/Users/xuexianmao/venu/jum3/lib/python3.6/site-packages/amqp/transport.py", line 161, in _connect
    self.sock.connect(sa)
ConnectionRefusedError: [Errno 61] Connection refused

During handling of the above exception, another exception occurred:

Traceback (most recent call last):
  File "/Users/xuexianmao/venu/jum3/lib/python3.6/site-packages/kombu/connection.py", line 414, in _reraise_as_library_errors
    yield
  File "/Users/xuexianmao/venu/jum3/lib/python3.6/site-packages/kombu/connection.py", line 515, in _ensured
    reraise_as_library_errors=False,
  File "/Users/xuexianmao/venu/jum3/lib/python3.6/site-packages/kombu/connection.py", line 405, in ensure_connection
    callback)
  File "/Users/xuexianmao/venu/jum3/lib/python3.6/site-packages/kombu/utils/functional.py", line 333, in retry_over_time
    return fun(*args, **kwargs)
  File "/Users/xuexianmao/venu/jum3/lib/python3.6/site-packages/kombu/connection.py", line 261, in connect
    return self.connection
  File "/Users/xuexianmao/venu/jum3/lib/python3.6/site-packages/kombu/connection.py", line 802, in connection
    self._connection = self._establish_connection()
  File "/Users/xuexianmao/venu/jum3/lib/python3.6/site-packages/kombu/connection.py", line 757, in _establish_connection
    conn = self.transport.establish_connection()
  File "/Users/xuexianmao/venu/jum3/lib/python3.6/site-packages/kombu/transport/pyamqp.py", line 130, in establish_connection
    conn.connect()
  File "/Users/xuexianmao/venu/jum3/lib/python3.6/site-packages/amqp/connection.py", line 294, in connect
    self.transport.connect()
  File "/Users/xuexianmao/venu/jum3/lib/python3.6/site-packages/amqp/transport.py", line 120, in connect
    self._connect(self.host, self.port, self.connect_timeout)
  File "/Users/xuexianmao/venu/jum3/lib/python3.6/site-packages/amqp/transport.py", line 161, in _connect
    self.sock.connect(sa)
ConnectionRefusedError: [Errno 61] Connection refused

During handling of the above exception, another exception occurred:

Traceback (most recent call last):
  File "/Users/xuexianmao/venu/jum3/lib/python3.6/site-packages/django/core/handlers/exception.py", line 41, in inner
    response = get_response(request)
  File "/Users/xuexianmao/venu/jum3/lib/python3.6/site-packages/django/core/handlers/base.py", line 187, in _get_response
    response = self.process_exception_by_middleware(e, request)
  File "/Users/xuexianmao/venu/jum3/lib/python3.6/site-packages/django/core/handlers/base.py", line 185, in _get_response
    response = wrapped_callback(request, *callback_args, **callback_kwargs)
  File "/usr/local/Cellar/python3/3.6.3/Frameworks/Python.framework/Versions/3.6/lib/python3.6/contextlib.py", line 52, in inner
    return func(*args, **kwds)
  File "/Users/xuexianmao/venu/jum3/lib/python3.6/site-packages/django/views/generic/base.py", line 68, in view
    return self.dispatch(request, *args, **kwargs)
  File "/Users/xuexianmao/venu/jum3/lib/python3.6/site-packages/django/utils/decorators.py", line 67, in _wrapper
    return bound_func(*args, **kwargs)
  File "/Users/xuexianmao/venu/jum3/lib/python3.6/site-packages/django/views/decorators/debug.py", line 76, in sensitive_post_parameters_wrapper
    return view(request, *args, **kwargs)
  File "/Users/xuexianmao/venu/jum3/lib/python3.6/site-packages/django/utils/decorators.py", line 63, in bound_func
    return func.__get__(self, type(self))(*args2, **kwargs2)
  File "/Users/xuexianmao/venu/jum3/lib/python3.6/site-packages/django/utils/decorators.py", line 67, in _wrapper
    return bound_func(*args, **kwargs)
  File "/Users/xuexianmao/venu/jum3/lib/python3.6/site-packages/django/utils/decorators.py", line 149, in _wrapped_view
    response = view_func(request, *args, **kwargs)
  File "/Users/xuexianmao/venu/jum3/lib/python3.6/site-packages/django/utils/decorators.py", line 63, in bound_func
    return func.__get__(self, type(self))(*args2, **kwargs2)
  File "/Users/xuexianmao/venu/jum3/lib/python3.6/site-packages/django/utils/decorators.py", line 67, in _wrapper
    return bound_func(*args, **kwargs)
  File "/Users/xuexianmao/venu/jum3/lib/python3.6/site-packages/django/views/decorators/cache.py", line 57, in _wrapped_view_func
    response = view_func(request, *args, **kwargs)
  File "/Users/xuexianmao/venu/jum3/lib/python3.6/site-packages/django/utils/decorators.py", line 63, in bound_func
    return func.__get__(self, type(self))(*args2, **kwargs2)
  File "/Users/xuexianmao/venu/jum3/lib/python3.6/site-packages/django/views/generic/base.py", line 88, in dispatch
    return handler(request, *args, **kwargs)
  File "/Users/xuexianmao/venu/jum3/lib/python3.6/site-packages/django/views/generic/edit.py", line 183, in post
    return self.form_valid(form)
  File "/Users/xuexianmao/PycharmProjects/diting/apps/users/views/login.py", line 68, in form_valid
    ip=login_ip, user_agent=user_agent
  File "/Users/xuexianmao/venu/jum3/lib/python3.6/site-packages/celery/app/task.py", line 413, in delay
    return self.apply_async(args, kwargs)
  File "/Users/xuexianmao/venu/jum3/lib/python3.6/site-packages/celery/app/task.py", line 536, in apply_async
    **options
  File "/Users/xuexianmao/venu/jum3/lib/python3.6/site-packages/celery/app/base.py", line 737, in send_task
    amqp.send_task_message(P, name, message, **options)
  File "/Users/xuexianmao/venu/jum3/lib/python3.6/site-packages/celery/app/amqp.py", line 554, in send_task_message
    **properties
  File "/Users/xuexianmao/venu/jum3/lib/python3.6/site-packages/kombu/messaging.py", line 181, in publish
    exchange_name, declare,
  File "/Users/xuexianmao/venu/jum3/lib/python3.6/site-packages/kombu/connection.py", line 527, in _ensured
    errback and errback(exc, 0)
  File "/usr/local/Cellar/python3/3.6.3/Frameworks/Python.framework/Versions/3.6/lib/python3.6/contextlib.py", line 99, in __exit__
    self.gen.throw(type, value, traceback)
  File "/Users/xuexianmao/venu/jum3/lib/python3.6/site-packages/kombu/connection.py", line 419, in _reraise_as_library_errors
    sys.exc_info()[2])
  File "/Users/xuexianmao/venu/jum3/lib/python3.6/site-packages/vine/five.py", line 178, in reraise
    raise value.with_traceback(tb)
  File "/Users/xuexianmao/venu/jum3/lib/python3.6/site-packages/kombu/connection.py", line 414, in _reraise_as_library_errors
    yield
  File "/Users/xuexianmao/venu/jum3/lib/python3.6/site-packages/kombu/connection.py", line 515, in _ensured
    reraise_as_library_errors=False,
  File "/Users/xuexianmao/venu/jum3/lib/python3.6/site-packages/kombu/connection.py", line 405, in ensure_connection
    callback)
  File "/Users/xuexianmao/venu/jum3/lib/python3.6/site-packages/kombu/utils/functional.py", line 333, in retry_over_time
    return fun(*args, **kwargs)
  File "/Users/xuexianmao/venu/jum3/lib/python3.6/site-packages/kombu/connection.py", line 261, in connect
    return self.connection
  File "/Users/xuexianmao/venu/jum3/lib/python3.6/site-packages/kombu/connection.py", line 802, in connection
    self._connection = self._establish_connection()
  File "/Users/xuexianmao/venu/jum3/lib/python3.6/site-packages/kombu/connection.py", line 757, in _establish_connection
    conn = self.transport.establish_connection()
  File "/Users/xuexianmao/venu/jum3/lib/python3.6/site-packages/kombu/transport/pyamqp.py", line 130, in establish_connection
    conn.connect()
  File "/Users/xuexianmao/venu/jum3/lib/python3.6/site-packages/amqp/connection.py", line 294, in connect
    self.transport.connect()
  File "/Users/xuexianmao/venu/jum3/lib/python3.6/site-packages/amqp/transport.py", line 120, in connect
    self._connect(self.host, self.port, self.connect_timeout)
  File "/Users/xuexianmao/venu/jum3/lib/python3.6/site-packages/amqp/transport.py", line 161, in _connect
    self.sock.connect(sa)
kombu.exceptions.OperationalError: [Errno 61] Connection refused
2018-04-13 19:47:49 [basehttp ERROR] "POST /users/login?next=/ HTTP/1.1" 500 363586
2018-04-13 19:48:09 [basehttp WARNING] "POST /users/login?next=/ HTTP/1.1" 403 2497
2018-04-13 19:48:11 [basehttp INFO] "GET / HTTP/1.1" 302 0
2018-04-13 19:48:11 [basehttp INFO] "GET /users/login?next=/ HTTP/1.1" 200 4754
2018-04-13 19:48:12 [basehttp INFO] "GET /captcha/image/fdada0527909f70b6b473ea82a3be84c763fc59a/ HTTP/1.1" 200 4009
2018-04-13 19:48:12 [basehttp INFO] "GET /static/img/facio.ico HTTP/1.1" 200 1744
2018-04-13 19:48:19 [exception ERROR] Internal Server Error: /users/login
Traceback (most recent call last):
  File "/Users/xuexianmao/venu/jum3/lib/python3.6/site-packages/kombu/utils/functional.py", line 36, in __call__
    return self.__value__
AttributeError: 'ChannelPromise' object has no attribute '__value__'

During handling of the above exception, another exception occurred:

Traceback (most recent call last):
  File "/Users/xuexianmao/venu/jum3/lib/python3.6/site-packages/kombu/connection.py", line 494, in _ensured
    return fun(*args, **kwargs)
  File "/Users/xuexianmao/venu/jum3/lib/python3.6/site-packages/kombu/messaging.py", line 187, in _publish
    channel = self.channel
  File "/Users/xuexianmao/venu/jum3/lib/python3.6/site-packages/kombu/messaging.py", line 209, in _get_channel
    channel = self._channel = channel()
  File "/Users/xuexianmao/venu/jum3/lib/python3.6/site-packages/kombu/utils/functional.py", line 38, in __call__
    value = self.__value__ = self.__contract__()
  File "/Users/xuexianmao/venu/jum3/lib/python3.6/site-packages/kombu/messaging.py", line 224, in <lambda>
    channel = ChannelPromise(lambda: connection.default_channel)
  File "/Users/xuexianmao/venu/jum3/lib/python3.6/site-packages/kombu/connection.py", line 819, in default_channel
    self.connection
  File "/Users/xuexianmao/venu/jum3/lib/python3.6/site-packages/kombu/connection.py", line 802, in connection
    self._connection = self._establish_connection()
  File "/Users/xuexianmao/venu/jum3/lib/python3.6/site-packages/kombu/connection.py", line 757, in _establish_connection
    conn = self.transport.establish_connection()
  File "/Users/xuexianmao/venu/jum3/lib/python3.6/site-packages/kombu/transport/pyamqp.py", line 130, in establish_connection
    conn.connect()
  File "/Users/xuexianmao/venu/jum3/lib/python3.6/site-packages/amqp/connection.py", line 294, in connect
    self.transport.connect()
  File "/Users/xuexianmao/venu/jum3/lib/python3.6/site-packages/amqp/transport.py", line 120, in connect
    self._connect(self.host, self.port, self.connect_timeout)
  File "/Users/xuexianmao/venu/jum3/lib/python3.6/site-packages/amqp/transport.py", line 161, in _connect
    self.sock.connect(sa)
ConnectionRefusedError: [Errno 61] Connection refused

During handling of the above exception, another exception occurred:

Traceback (most recent call last):
  File "/Users/xuexianmao/venu/jum3/lib/python3.6/site-packages/kombu/connection.py", line 414, in _reraise_as_library_errors
    yield
  File "/Users/xuexianmao/venu/jum3/lib/python3.6/site-packages/kombu/connection.py", line 515, in _ensured
    reraise_as_library_errors=False,
  File "/Users/xuexianmao/venu/jum3/lib/python3.6/site-packages/kombu/connection.py", line 405, in ensure_connection
    callback)
  File "/Users/xuexianmao/venu/jum3/lib/python3.6/site-packages/kombu/utils/functional.py", line 333, in retry_over_time
    return fun(*args, **kwargs)
  File "/Users/xuexianmao/venu/jum3/lib/python3.6/site-packages/kombu/connection.py", line 261, in connect
    return self.connection
  File "/Users/xuexianmao/venu/jum3/lib/python3.6/site-packages/kombu/connection.py", line 802, in connection
    self._connection = self._establish_connection()
  File "/Users/xuexianmao/venu/jum3/lib/python3.6/site-packages/kombu/connection.py", line 757, in _establish_connection
    conn = self.transport.establish_connection()
  File "/Users/xuexianmao/venu/jum3/lib/python3.6/site-packages/kombu/transport/pyamqp.py", line 130, in establish_connection
    conn.connect()
  File "/Users/xuexianmao/venu/jum3/lib/python3.6/site-packages/amqp/connection.py", line 294, in connect
    self.transport.connect()
  File "/Users/xuexianmao/venu/jum3/lib/python3.6/site-packages/amqp/transport.py", line 120, in connect
    self._connect(self.host, self.port, self.connect_timeout)
  File "/Users/xuexianmao/venu/jum3/lib/python3.6/site-packages/amqp/transport.py", line 161, in _connect
    self.sock.connect(sa)
ConnectionRefusedError: [Errno 61] Connection refused

During handling of the above exception, another exception occurred:

Traceback (most recent call last):
  File "/Users/xuexianmao/venu/jum3/lib/python3.6/site-packages/django/core/handlers/exception.py", line 41, in inner
    response = get_response(request)
  File "/Users/xuexianmao/venu/jum3/lib/python3.6/site-packages/django/core/handlers/base.py", line 187, in _get_response
    response = self.process_exception_by_middleware(e, request)
  File "/Users/xuexianmao/venu/jum3/lib/python3.6/site-packages/django/core/handlers/base.py", line 185, in _get_response
    response = wrapped_callback(request, *callback_args, **callback_kwargs)
  File "/usr/local/Cellar/python3/3.6.3/Frameworks/Python.framework/Versions/3.6/lib/python3.6/contextlib.py", line 52, in inner
    return func(*args, **kwds)
  File "/Users/xuexianmao/venu/jum3/lib/python3.6/site-packages/django/views/generic/base.py", line 68, in view
    return self.dispatch(request, *args, **kwargs)
  File "/Users/xuexianmao/venu/jum3/lib/python3.6/site-packages/django/utils/decorators.py", line 67, in _wrapper
    return bound_func(*args, **kwargs)
  File "/Users/xuexianmao/venu/jum3/lib/python3.6/site-packages/django/views/decorators/debug.py", line 76, in sensitive_post_parameters_wrapper
    return view(request, *args, **kwargs)
  File "/Users/xuexianmao/venu/jum3/lib/python3.6/site-packages/django/utils/decorators.py", line 63, in bound_func
    return func.__get__(self, type(self))(*args2, **kwargs2)
  File "/Users/xuexianmao/venu/jum3/lib/python3.6/site-packages/django/utils/decorators.py", line 67, in _wrapper
    return bound_func(*args, **kwargs)
  File "/Users/xuexianmao/venu/jum3/lib/python3.6/site-packages/django/utils/decorators.py", line 149, in _wrapped_view
    response = view_func(request, *args, **kwargs)
  File "/Users/xuexianmao/venu/jum3/lib/python3.6/site-packages/django/utils/decorators.py", line 63, in bound_func
    return func.__get__(self, type(self))(*args2, **kwargs2)
  File "/Users/xuexianmao/venu/jum3/lib/python3.6/site-packages/django/utils/decorators.py", line 67, in _wrapper
    return bound_func(*args, **kwargs)
  File "/Users/xuexianmao/venu/jum3/lib/python3.6/site-packages/django/views/decorators/cache.py", line 57, in _wrapped_view_func
    response = view_func(request, *args, **kwargs)
  File "/Users/xuexianmao/venu/jum3/lib/python3.6/site-packages/django/utils/decorators.py", line 63, in bound_func
    return func.__get__(self, type(self))(*args2, **kwargs2)
  File "/Users/xuexianmao/venu/jum3/lib/python3.6/site-packages/django/views/generic/base.py", line 88, in dispatch
    return handler(request, *args, **kwargs)
  File "/Users/xuexianmao/venu/jum3/lib/python3.6/site-packages/django/views/generic/edit.py", line 183, in post
    return self.form_valid(form)
  File "/Users/xuexianmao/PycharmProjects/diting/apps/users/views/login.py", line 68, in form_valid
    ip=login_ip, user_agent=user_agent
  File "/Users/xuexianmao/venu/jum3/lib/python3.6/site-packages/celery/app/task.py", line 413, in delay
    return self.apply_async(args, kwargs)
  File "/Users/xuexianmao/venu/jum3/lib/python3.6/site-packages/celery/app/task.py", line 536, in apply_async
    **options
  File "/Users/xuexianmao/venu/jum3/lib/python3.6/site-packages/celery/app/base.py", line 737, in send_task
    amqp.send_task_message(P, name, message, **options)
  File "/Users/xuexianmao/venu/jum3/lib/python3.6/site-packages/celery/app/amqp.py", line 554, in send_task_message
    **properties
  File "/Users/xuexianmao/venu/jum3/lib/python3.6/site-packages/kombu/messaging.py", line 181, in publish
    exchange_name, declare,
  File "/Users/xuexianmao/venu/jum3/lib/python3.6/site-packages/kombu/connection.py", line 527, in _ensured
    errback and errback(exc, 0)
  File "/usr/local/Cellar/python3/3.6.3/Frameworks/Python.framework/Versions/3.6/lib/python3.6/contextlib.py", line 99, in __exit__
    self.gen.throw(type, value, traceback)
  File "/Users/xuexianmao/venu/jum3/lib/python3.6/site-packages/kombu/connection.py", line 419, in _reraise_as_library_errors
    sys.exc_info()[2])
  File "/Users/xuexianmao/venu/jum3/lib/python3.6/site-packages/vine/five.py", line 178, in reraise
    raise value.with_traceback(tb)
  File "/Users/xuexianmao/venu/jum3/lib/python3.6/site-packages/kombu/connection.py", line 414, in _reraise_as_library_errors
    yield
  File "/Users/xuexianmao/venu/jum3/lib/python3.6/site-packages/kombu/connection.py", line 515, in _ensured
    reraise_as_library_errors=False,
  File "/Users/xuexianmao/venu/jum3/lib/python3.6/site-packages/kombu/connection.py", line 405, in ensure_connection
    callback)
  File "/Users/xuexianmao/venu/jum3/lib/python3.6/site-packages/kombu/utils/functional.py", line 333, in retry_over_time
    return fun(*args, **kwargs)
  File "/Users/xuexianmao/venu/jum3/lib/python3.6/site-packages/kombu/connection.py", line 261, in connect
    return self.connection
  File "/Users/xuexianmao/venu/jum3/lib/python3.6/site-packages/kombu/connection.py", line 802, in connection
    self._connection = self._establish_connection()
  File "/Users/xuexianmao/venu/jum3/lib/python3.6/site-packages/kombu/connection.py", line 757, in _establish_connection
    conn = self.transport.establish_connection()
  File "/Users/xuexianmao/venu/jum3/lib/python3.6/site-packages/kombu/transport/pyamqp.py", line 130, in establish_connection
    conn.connect()
  File "/Users/xuexianmao/venu/jum3/lib/python3.6/site-packages/amqp/connection.py", line 294, in connect
    self.transport.connect()
  File "/Users/xuexianmao/venu/jum3/lib/python3.6/site-packages/amqp/transport.py", line 120, in connect
    self._connect(self.host, self.port, self.connect_timeout)
  File "/Users/xuexianmao/venu/jum3/lib/python3.6/site-packages/amqp/transport.py", line 161, in _connect
    self.sock.connect(sa)
kombu.exceptions.OperationalError: [Errno 61] Connection refused
2018-04-13 19:48:19 [basehttp ERROR] "POST /users/login?next=/ HTTP/1.1" 500 363586
2018-04-13 19:49:42 [basehttp WARNING] "POST /users/login?next=/ HTTP/1.1" 403 2497
2018-04-13 19:49:45 [basehttp INFO] "GET / HTTP/1.1" 302 0
2018-04-13 19:49:45 [basehttp INFO] "GET /users/login?next=/ HTTP/1.1" 200 4754
2018-04-13 19:49:45 [basehttp INFO] "GET /captcha/image/6ffa733181986053606b62dd73543c63cfc88534/ HTTP/1.1" 200 3703
2018-04-13 19:49:45 [basehttp INFO] "GET /static/img/facio.ico HTTP/1.1" 200 1744
2018-04-13 19:49:51 [basehttp INFO] "POST /users/login?next=/ HTTP/1.1" 302 0
2018-04-13 19:49:51 [exception ERROR] Internal Server Error: /
Traceback (most recent call last):
  File "/Users/xuexianmao/venu/jum3/lib/python3.6/site-packages/django/core/handlers/exception.py", line 41, in inner
    response = get_response(request)
  File "/Users/xuexianmao/venu/jum3/lib/python3.6/site-packages/django/core/handlers/base.py", line 187, in _get_response
    response = self.process_exception_by_middleware(e, request)
  File "/Users/xuexianmao/venu/jum3/lib/python3.6/site-packages/django/core/handlers/base.py", line 185, in _get_response
    response = wrapped_callback(request, *callback_args, **callback_kwargs)
  File "/usr/local/Cellar/python3/3.6.3/Frameworks/Python.framework/Versions/3.6/lib/python3.6/contextlib.py", line 52, in inner
    return func(*args, **kwds)
  File "/Users/xuexianmao/venu/jum3/lib/python3.6/site-packages/django/views/generic/base.py", line 68, in view
    return self.dispatch(request, *args, **kwargs)
  File "/Users/xuexianmao/venu/jum3/lib/python3.6/site-packages/django/contrib/auth/mixins.py", line 56, in dispatch
    return super(LoginRequiredMixin, self).dispatch(request, *args, **kwargs)
  File "/Users/xuexianmao/venu/jum3/lib/python3.6/site-packages/django/views/generic/base.py", line 88, in dispatch
    return handler(request, *args, **kwargs)
  File "/Users/xuexianmao/PycharmProjects/diting/apps/diting/views.py", line 25, in get
    return super(IndexView, self).get(request, *args, **kwargs)
  File "/Users/xuexianmao/venu/jum3/lib/python3.6/site-packages/django/views/generic/base.py", line 155, in get
    context = self.get_context_data(**kwargs)
  File "/Users/xuexianmao/PycharmProjects/diting/apps/diting/views.py", line 83, in get_context_data
    self.session_month_dates = self.session_month.dates('date_start', 'day')
AttributeError: 'NoneType' object has no attribute 'dates'
2018-04-13 19:49:51 [basehttp ERROR] "GET / HTTP/1.1" 500 100044
2018-04-13 19:59:02 [exception ERROR] Internal Server Error: /
Traceback (most recent call last):
  File "/Users/xuexianmao/venu/jum3/lib/python3.6/site-packages/django/urls/base.py", line 77, in reverse
    extra, resolver = resolver.namespace_dict[ns]
KeyError: 'assets'

During handling of the above exception, another exception occurred:

Traceback (most recent call last):
  File "/Users/xuexianmao/venu/jum3/lib/python3.6/site-packages/django/core/handlers/exception.py", line 41, in inner
    response = get_response(request)
  File "/Users/xuexianmao/venu/jum3/lib/python3.6/site-packages/django/core/handlers/base.py", line 217, in _get_response
    response = self.process_exception_by_middleware(e, request)
  File "/Users/xuexianmao/venu/jum3/lib/python3.6/site-packages/django/core/handlers/base.py", line 215, in _get_response
    response = response.render()
  File "/Users/xuexianmao/venu/jum3/lib/python3.6/site-packages/django/template/response.py", line 107, in render
    self.content = self.rendered_content
  File "/Users/xuexianmao/venu/jum3/lib/python3.6/site-packages/django/template/response.py", line 84, in rendered_content
    content = template.render(context, self._request)
  File "/Users/xuexianmao/venu/jum3/lib/python3.6/site-packages/django/template/backends/django.py", line 66, in render
    return self.template.render(context)
  File "/Users/xuexianmao/venu/jum3/lib/python3.6/site-packages/django/template/base.py", line 207, in render
    return self._render(context)
  File "/Users/xuexianmao/venu/jum3/lib/python3.6/site-packages/django/template/base.py", line 199, in _render
    return self.nodelist.render(context)
  File "/Users/xuexianmao/venu/jum3/lib/python3.6/site-packages/django/template/base.py", line 990, in render
    bit = node.render_annotated(context)
  File "/Users/xuexianmao/venu/jum3/lib/python3.6/site-packages/django/template/base.py", line 957, in render_annotated
    return self.render(context)
  File "/Users/xuexianmao/venu/jum3/lib/python3.6/site-packages/django/template/loader_tags.py", line 177, in render
    return compiled_parent._render(context)
  File "/Users/xuexianmao/venu/jum3/lib/python3.6/site-packages/django/template/base.py", line 199, in _render
    return self.nodelist.render(context)
  File "/Users/xuexianmao/venu/jum3/lib/python3.6/site-packages/django/template/base.py", line 990, in render
    bit = node.render_annotated(context)
  File "/Users/xuexianmao/venu/jum3/lib/python3.6/site-packages/django/template/base.py", line 957, in render_annotated
    return self.render(context)
  File "/Users/xuexianmao/venu/jum3/lib/python3.6/site-packages/django/template/loader_tags.py", line 216, in render
    return template.render(context)
  File "/Users/xuexianmao/venu/jum3/lib/python3.6/site-packages/django/template/base.py", line 209, in render
    return self._render(context)
  File "/Users/xuexianmao/venu/jum3/lib/python3.6/site-packages/django/template/base.py", line 199, in _render
    return self.nodelist.render(context)
  File "/Users/xuexianmao/venu/jum3/lib/python3.6/site-packages/django/template/base.py", line 990, in render
    bit = node.render_annotated(context)
  File "/Users/xuexianmao/venu/jum3/lib/python3.6/site-packages/django/template/base.py", line 957, in render_annotated
    return self.render(context)
  File "/Users/xuexianmao/venu/jum3/lib/python3.6/site-packages/django/template/loader_tags.py", line 216, in render
    return template.render(context)
  File "/Users/xuexianmao/venu/jum3/lib/python3.6/site-packages/django/template/base.py", line 209, in render
    return self._render(context)
  File "/Users/xuexianmao/venu/jum3/lib/python3.6/site-packages/django/template/base.py", line 199, in _render
    return self.nodelist.render(context)
  File "/Users/xuexianmao/venu/jum3/lib/python3.6/site-packages/django/template/base.py", line 990, in render
    bit = node.render_annotated(context)
  File "/Users/xuexianmao/venu/jum3/lib/python3.6/site-packages/django/template/base.py", line 957, in render_annotated
    return self.render(context)
  File "/Users/xuexianmao/venu/jum3/lib/python3.6/site-packages/django/template/defaulttags.py", line 458, in render
    url = reverse(view_name, args=args, kwargs=kwargs, current_app=current_app)
  File "/Users/xuexianmao/venu/jum3/lib/python3.6/site-packages/django/urls/base.py", line 87, in reverse
    raise NoReverseMatch("%s is not a registered namespace" % key)
django.urls.exceptions.NoReverseMatch: 'assets' is not a registered namespace
2018-04-13 19:59:02 [basehttp ERROR] "GET / HTTP/1.1" 500 185853
2018-04-13 20:00:31 [exception ERROR] Internal Server Error: /
Traceback (most recent call last):
  File "/Users/xuexianmao/venu/jum3/lib/python3.6/site-packages/django/urls/base.py", line 77, in reverse
    extra, resolver = resolver.namespace_dict[ns]
KeyError: 'assets'

During handling of the above exception, another exception occurred:

Traceback (most recent call last):
  File "/Users/xuexianmao/venu/jum3/lib/python3.6/site-packages/django/core/handlers/exception.py", line 41, in inner
    response = get_response(request)
  File "/Users/xuexianmao/venu/jum3/lib/python3.6/site-packages/django/core/handlers/base.py", line 217, in _get_response
    response = self.process_exception_by_middleware(e, request)
  File "/Users/xuexianmao/venu/jum3/lib/python3.6/site-packages/django/core/handlers/base.py", line 215, in _get_response
    response = response.render()
  File "/Users/xuexianmao/venu/jum3/lib/python3.6/site-packages/django/template/response.py", line 107, in render
    self.content = self.rendered_content
  File "/Users/xuexianmao/venu/jum3/lib/python3.6/site-packages/django/template/response.py", line 84, in rendered_content
    content = template.render(context, self._request)
  File "/Users/xuexianmao/venu/jum3/lib/python3.6/site-packages/django/template/backends/django.py", line 66, in render
    return self.template.render(context)
  File "/Users/xuexianmao/venu/jum3/lib/python3.6/site-packages/django/template/base.py", line 207, in render
    return self._render(context)
  File "/Users/xuexianmao/venu/jum3/lib/python3.6/site-packages/django/template/base.py", line 199, in _render
    return self.nodelist.render(context)
  File "/Users/xuexianmao/venu/jum3/lib/python3.6/site-packages/django/template/base.py", line 990, in render
    bit = node.render_annotated(context)
  File "/Users/xuexianmao/venu/jum3/lib/python3.6/site-packages/django/template/base.py", line 957, in render_annotated
    return self.render(context)
  File "/Users/xuexianmao/venu/jum3/lib/python3.6/site-packages/django/template/loader_tags.py", line 177, in render
    return compiled_parent._render(context)
  File "/Users/xuexianmao/venu/jum3/lib/python3.6/site-packages/django/template/base.py", line 199, in _render
    return self.nodelist.render(context)
  File "/Users/xuexianmao/venu/jum3/lib/python3.6/site-packages/django/template/base.py", line 990, in render
    bit = node.render_annotated(context)
  File "/Users/xuexianmao/venu/jum3/lib/python3.6/site-packages/django/template/base.py", line 957, in render_annotated
    return self.render(context)
  File "/Users/xuexianmao/venu/jum3/lib/python3.6/site-packages/django/template/loader_tags.py", line 216, in render
    return template.render(context)
  File "/Users/xuexianmao/venu/jum3/lib/python3.6/site-packages/django/template/base.py", line 209, in render
    return self._render(context)
  File "/Users/xuexianmao/venu/jum3/lib/python3.6/site-packages/django/template/base.py", line 199, in _render
    return self.nodelist.render(context)
  File "/Users/xuexianmao/venu/jum3/lib/python3.6/site-packages/django/template/base.py", line 990, in render
    bit = node.render_annotated(context)
  File "/Users/xuexianmao/venu/jum3/lib/python3.6/site-packages/django/template/base.py", line 957, in render_annotated
    return self.render(context)
  File "/Users/xuexianmao/venu/jum3/lib/python3.6/site-packages/django/template/loader_tags.py", line 216, in render
    return template.render(context)
  File "/Users/xuexianmao/venu/jum3/lib/python3.6/site-packages/django/template/base.py", line 209, in render
    return self._render(context)
  File "/Users/xuexianmao/venu/jum3/lib/python3.6/site-packages/django/template/base.py", line 199, in _render
    return self.nodelist.render(context)
  File "/Users/xuexianmao/venu/jum3/lib/python3.6/site-packages/django/template/base.py", line 990, in render
    bit = node.render_annotated(context)
  File "/Users/xuexianmao/venu/jum3/lib/python3.6/site-packages/django/template/base.py", line 957, in render_annotated
    return self.render(context)
  File "/Users/xuexianmao/venu/jum3/lib/python3.6/site-packages/django/template/defaulttags.py", line 458, in render
    url = reverse(view_name, args=args, kwargs=kwargs, current_app=current_app)
  File "/Users/xuexianmao/venu/jum3/lib/python3.6/site-packages/django/urls/base.py", line 87, in reverse
    raise NoReverseMatch("%s is not a registered namespace" % key)
django.urls.exceptions.NoReverseMatch: 'assets' is not a registered namespace
2018-04-13 20:00:31 [basehttp ERROR] "GET / HTTP/1.1" 500 185853
2018-04-13 20:01:23 [exception ERROR] Internal Server Error: /
Traceback (most recent call last):
  File "/Users/xuexianmao/venu/jum3/lib/python3.6/site-packages/django/core/handlers/exception.py", line 41, in inner
    response = get_response(request)
  File "/Users/xuexianmao/venu/jum3/lib/python3.6/site-packages/django/core/handlers/base.py", line 217, in _get_response
    response = self.process_exception_by_middleware(e, request)
  File "/Users/xuexianmao/venu/jum3/lib/python3.6/site-packages/django/core/handlers/base.py", line 215, in _get_response
    response = response.render()
  File "/Users/xuexianmao/venu/jum3/lib/python3.6/site-packages/django/template/response.py", line 107, in render
    self.content = self.rendered_content
  File "/Users/xuexianmao/venu/jum3/lib/python3.6/site-packages/django/template/response.py", line 84, in rendered_content
    content = template.render(context, self._request)
  File "/Users/xuexianmao/venu/jum3/lib/python3.6/site-packages/django/template/backends/django.py", line 66, in render
    return self.template.render(context)
  File "/Users/xuexianmao/venu/jum3/lib/python3.6/site-packages/django/template/base.py", line 207, in render
    return self._render(context)
  File "/Users/xuexianmao/venu/jum3/lib/python3.6/site-packages/django/template/base.py", line 199, in _render
    return self.nodelist.render(context)
  File "/Users/xuexianmao/venu/jum3/lib/python3.6/site-packages/django/template/base.py", line 990, in render
    bit = node.render_annotated(context)
  File "/Users/xuexianmao/venu/jum3/lib/python3.6/site-packages/django/template/base.py", line 957, in render_annotated
    return self.render(context)
  File "/Users/xuexianmao/venu/jum3/lib/python3.6/site-packages/django/template/loader_tags.py", line 177, in render
    return compiled_parent._render(context)
  File "/Users/xuexianmao/venu/jum3/lib/python3.6/site-packages/django/template/base.py", line 199, in _render
    return self.nodelist.render(context)
  File "/Users/xuexianmao/venu/jum3/lib/python3.6/site-packages/django/template/base.py", line 990, in render
    bit = node.render_annotated(context)
  File "/Users/xuexianmao/venu/jum3/lib/python3.6/site-packages/django/template/base.py", line 957, in render_annotated
    return self.render(context)
  File "/Users/xuexianmao/venu/jum3/lib/python3.6/site-packages/django/template/loader_tags.py", line 216, in render
    return template.render(context)
  File "/Users/xuexianmao/venu/jum3/lib/python3.6/site-packages/django/template/base.py", line 209, in render
    return self._render(context)
  File "/Users/xuexianmao/venu/jum3/lib/python3.6/site-packages/django/template/base.py", line 199, in _render
    return self.nodelist.render(context)
  File "/Users/xuexianmao/venu/jum3/lib/python3.6/site-packages/django/template/base.py", line 990, in render
    bit = node.render_annotated(context)
  File "/Users/xuexianmao/venu/jum3/lib/python3.6/site-packages/django/template/base.py", line 957, in render_annotated
    return self.render(context)
  File "/Users/xuexianmao/venu/jum3/lib/python3.6/site-packages/django/template/loader_tags.py", line 216, in render
    return template.render(context)
  File "/Users/xuexianmao/venu/jum3/lib/python3.6/site-packages/django/template/base.py", line 209, in render
    return self._render(context)
  File "/Users/xuexianmao/venu/jum3/lib/python3.6/site-packages/django/template/base.py", line 199, in _render
    return self.nodelist.render(context)
  File "/Users/xuexianmao/venu/jum3/lib/python3.6/site-packages/django/template/base.py", line 990, in render
    bit = node.render_annotated(context)
  File "/Users/xuexianmao/venu/jum3/lib/python3.6/site-packages/django/template/base.py", line 957, in render_annotated
    return self.render(context)
  File "/Users/xuexianmao/venu/jum3/lib/python3.6/site-packages/django/template/defaulttags.py", line 458, in render
    url = reverse(view_name, args=args, kwargs=kwargs, current_app=current_app)
  File "/Users/xuexianmao/venu/jum3/lib/python3.6/site-packages/django/urls/base.py", line 91, in reverse
    return force_text(iri_to_uri(resolver._reverse_with_prefix(view, prefix, *args, **kwargs)))
  File "/Users/xuexianmao/venu/jum3/lib/python3.6/site-packages/django/urls/resolvers.py", line 497, in _reverse_with_prefix
    raise NoReverseMatch(msg)
django.urls.exceptions.NoReverseMatch: Reverse for 'users-list' not found. 'users-list' is not a valid view function or pattern name.
2018-04-13 20:01:23 [basehttp ERROR] "GET / HTTP/1.1" 500 185981
2018-04-13 20:01:33 [basehttp INFO] "GET / HTTP/1.1" 200 8964
2018-04-13 20:01:33 [basehttp WARNING] "GET /static/ionicons/css/ionicons.min.css HTTP/1.1" 404 1801
2018-04-13 20:01:33 [basehttp INFO] "GET /static/js/plugins/metisMenu/jquery.metisMenu.js HTTP/1.1" 200 3984
2018-04-13 20:01:33 [basehttp INFO] "GET /static/js/plugins/toastr/toastr.min.js HTTP/1.1" 200 5216
2018-04-13 20:01:33 [basehttp INFO] "GET /static/js/inspinia.js HTTP/1.1" 200 4636
2018-04-13 20:01:33 [basehttp INFO] "GET /static/img/logo-text.png HTTP/1.1" 200 18125
2018-04-13 20:01:33 [basehttp INFO] "GET /static/img/avatar/admin.png HTTP/1.1" 200 11750
2018-04-13 20:01:33 [basehttp WARNING] "GET /static/ionicons/css/ionicons.min.css HTTP/1.1" 404 1801
2018-04-13 20:01:33 [basehttp INFO] "GET /static/fonts/fontawesome-webfont.woff2?v=4.7.0 HTTP/1.1" 200 77160
2018-04-13 20:01:33 [basehttp INFO] "GET /static/img/facio.ico HTTP/1.1" 200 1744
2018-04-13 20:01:36 [basehttp INFO] "GET /navis/navi/ HTTP/1.1" 200 15813
2018-04-13 20:01:36 [basehttp WARNING] "GET /static/ionicons/css/ionicons.min.css HTTP/1.1" 404 1801
2018-04-13 20:01:36 [basehttp INFO] "GET /static/css/plugins/select2/select2.min.css HTTP/1.1" 200 15196
2018-04-13 20:01:36 [basehttp INFO] "GET /static/js/plugins/select2/select2.full.min.js HTTP/1.1" 200 75005
2018-04-13 20:01:36 [basehttp INFO] "GET /static/js/jquery.form.min.js HTTP/1.1" 200 15248
2018-04-13 20:01:36 [basehttp WARNING] "GET /static/ionicons/css/ionicons.min.css HTTP/1.1" 404 1801
2018-04-13 20:01:36 [basehttp INFO] "GET /static/fonts/glyphicons-halflings-regular.woff HTTP/1.1" 200 23424
2018-04-13 20:01:36 [basehttp INFO] "GET /api/navis/v1/navi/?_=1523620896773 HTTP/1.1" 200 2
2018-04-13 20:01:41 [basehttp INFO] "GET /users/user HTTP/1.1" 200 20827
2018-04-13 20:01:41 [basehttp WARNING] "GET /static/ionicons/css/ionicons.min.css HTTP/1.1" 404 1801
2018-04-13 20:01:41 [basehttp WARNING] "GET /static/ionicons/css/ionicons.min.css HTTP/1.1" 404 1801
2018-04-13 20:01:41 [basehttp INFO] "GET /api/users/v1/users/?_=1523620901571 HTTP/1.1" 200 556
2018-04-13 20:01:43 [basehttp INFO] "GET /users/user-group HTTP/1.1" 200 14444
2018-04-13 20:01:43 [basehttp WARNING] "GET /static/ionicons/css/ionicons.min.css HTTP/1.1" 404 1801
2018-04-13 20:01:43 [basehttp WARNING] "GET /static/ionicons/css/ionicons.min.css HTTP/1.1" 404 1801
2018-04-13 20:01:44 [basehttp INFO] "GET /api/users/v1/groups/?_=1523620903962 HTTP/1.1" 200 2
2018-04-13 20:01:45 [basehttp INFO] "GET /users/user-group/create HTTP/1.1" 200 11596
2018-04-13 20:01:45 [basehttp WARNING] "GET /static/ionicons/css/ionicons.min.css HTTP/1.1" 404 1801
2018-04-13 20:01:45 [basehttp WARNING] "GET /static/ionicons/css/ionicons.min.css HTTP/1.1" 404 1801
2018-04-13 20:01:48 [basehttp INFO] "GET / HTTP/1.1" 200 8964
2018-04-13 20:01:48 [basehttp WARNING] "GET /static/ionicons/css/ionicons.min.css HTTP/1.1" 404 1801
2018-04-13 20:01:52 [basehttp INFO] "GET /settings/ HTTP/1.1" 200 12431
2018-04-13 20:01:52 [basehttp WARNING] "GET /static/ionicons/css/ionicons.min.css HTTP/1.1" 404 1801
2018-04-13 20:01:52 [basehttp WARNING] "GET /static/ionicons/css/ionicons.min.css HTTP/1.1" 404 1801
2018-04-13 20:01:54 [basehttp INFO] "GET /settings/email/ HTTP/1.1" 200 14939
2018-04-13 20:01:54 [basehttp WARNING] "GET /static/ionicons/css/ionicons.min.css HTTP/1.1" 404 1801
2018-04-13 20:01:56 [basehttp INFO] "GET /settings/ldap/ HTTP/1.1" 200 16288
2018-04-13 20:01:56 [basehttp WARNING] "GET /static/ionicons/css/ionicons.min.css HTTP/1.1" 404 1801
2018-04-13 20:01:56 [basehttp WARNING] "GET /static/ionicons/css/ionicons.min.css HTTP/1.1" 404 1801
2018-04-13 20:01:57 [basehttp INFO] "GET /settings/terminal/ HTTP/1.1" 200 17985
2018-04-13 20:01:57 [basehttp WARNING] "GET /static/ionicons/css/ionicons.min.css HTTP/1.1" 404 1801
2018-04-13 20:01:58 [basehttp INFO] "GET /settings/ldap/ HTTP/1.1" 200 16288
2018-04-13 20:01:58 [basehttp WARNING] "GET /static/ionicons/css/ionicons.min.css HTTP/1.1" 404 1801
2018-04-13 20:01:58 [basehttp WARNING] "GET /static/ionicons/css/ionicons.min.css HTTP/1.1" 404 1801
2018-04-13 20:01:59 [basehttp INFO] "GET /settings/email/ HTTP/1.1" 200 14939
2018-04-13 20:01:59 [basehttp WARNING] "GET /static/ionicons/css/ionicons.min.css HTTP/1.1" 404 1801
2018-04-13 20:02:00 [basehttp INFO] "GET /settings/ HTTP/1.1" 200 12431
2018-04-13 20:02:01 [basehttp WARNING] "GET /static/ionicons/css/ionicons.min.css HTTP/1.1" 404 1801
2018-04-13 20:02:01 [basehttp WARNING] "GET /static/ionicons/css/ionicons.min.css HTTP/1.1" 404 1801
2018-04-13 20:02:02 [basehttp INFO] "GET /settings/ HTTP/1.1" 200 12431
2018-04-13 20:02:02 [basehttp WARNING] "GET /static/ionicons/css/ionicons.min.css HTTP/1.1" 404 1801
2018-04-13 20:02:03 [basehttp INFO] "GET / HTTP/1.1" 200 8964
2018-04-13 20:02:03 [basehttp WARNING] "GET /static/ionicons/css/ionicons.min.css HTTP/1.1" 404 1801
2018-04-13 20:02:03 [basehttp WARNING] "GET /static/ionicons/css/ionicons.min.css HTTP/1.1" 404 1801
2018-04-13 20:02:05 [basehttp INFO] "GET /users/user HTTP/1.1" 200 20827
2018-04-13 20:02:05 [basehttp WARNING] "GET /static/ionicons/css/ionicons.min.css HTTP/1.1" 404 1801
2018-04-13 20:02:05 [basehttp INFO] "GET /api/users/v1/users/?_=1523620925285 HTTP/1.1" 200 556
2018-04-13 20:02:06 [basehttp INFO] "GET /users/user-group HTTP/1.1" 200 14444
2018-04-13 20:02:06 [basehttp WARNING] "GET /static/ionicons/css/ionicons.min.css HTTP/1.1" 404 1801
2018-04-13 20:02:06 [basehttp WARNING] "GET /static/ionicons/css/ionicons.min.css HTTP/1.1" 404 1801
2018-04-13 20:02:06 [basehttp INFO] "GET /api/users/v1/groups/?_=1523620926256 HTTP/1.1" 200 2
2018-04-13 20:02:07 [basehttp INFO] "GET /users/user-group/create HTTP/1.1" 200 11596
2018-04-13 20:02:07 [basehttp WARNING] "GET /static/ionicons/css/ionicons.min.css HTTP/1.1" 404 1801
2018-04-13 20:02:07 [basehttp WARNING] "GET /static/ionicons/css/ionicons.min.css HTTP/1.1" 404 1801
2018-04-13 20:02:19 [basehttp INFO] "POST /users/user-group/create HTTP/1.1" 302 0
2018-04-13 20:02:19 [basehttp INFO] "GET /users/user-group HTTP/1.1" 200 14564
2018-04-13 20:02:20 [basehttp WARNING] "GET /static/ionicons/css/ionicons.min.css HTTP/1.1" 404 1801
2018-04-13 20:02:20 [basehttp WARNING] "GET /static/ionicons/css/ionicons.min.css HTTP/1.1" 404 1801
2018-04-13 20:02:20 [basehttp INFO] "GET /api/users/v1/groups/?_=1523620940057 HTTP/1.1" 200 219
2018-04-13 20:02:22 [basehttp INFO] "GET /users/user HTTP/1.1" 200 20827
2018-04-13 20:02:22 [basehttp WARNING] "GET /static/ionicons/css/ionicons.min.css HTTP/1.1" 404 1801
2018-04-13 20:02:22 [basehttp WARNING] "GET /static/ionicons/css/ionicons.min.css HTTP/1.1" 404 1801
2018-04-13 20:02:22 [basehttp INFO] "GET /api/users/v1/users/?_=1523620942375 HTTP/1.1" 200 599
2018-04-13 20:02:26 [basehttp INFO] "GET /users/user/61c39c1f-5b57-4268-8180-b6dda235aadd HTTP/1.1" 200 25520
2018-04-13 20:02:26 [basehttp WARNING] "GET /static/ionicons/css/ionicons.min.css HTTP/1.1" 404 1801
2018-04-13 20:02:26 [basehttp WARNING] "GET /static/ionicons/css/ionicons.min.css HTTP/1.1" 404 1801
2018-04-13 20:02:32 [basehttp INFO] "GET /users/user HTTP/1.1" 200 20827
2018-04-13 20:02:32 [basehttp WARNING] "GET /static/ionicons/css/ionicons.min.css HTTP/1.1" 404 1801
2018-04-13 20:02:32 [basehttp WARNING] "GET /static/ionicons/css/ionicons.min.css HTTP/1.1" 404 1801
2018-04-13 20:02:32 [basehttp INFO] "GET /api/users/v1/users/?_=1523620952438 HTTP/1.1" 200 599
2018-04-13 20:02:33 [basehttp INFO] "GET /users/user-group HTTP/1.1" 200 14444
2018-04-13 20:02:33 [basehttp WARNING] "GET /static/ionicons/css/ionicons.min.css HTTP/1.1" 404 1801
2018-04-13 20:02:33 [basehttp WARNING] "GET /static/ionicons/css/ionicons.min.css HTTP/1.1" 404 1801
2018-04-13 20:02:33 [basehttp INFO] "GET /api/users/v1/groups/?_=1523620953844 HTTP/1.1" 200 219
2018-04-13 20:02:37 [basehttp INFO] "GET /users/profile/ HTTP/1.1" 200 18029
2018-04-13 20:02:37 [basehttp WARNING] "GET /static/ionicons/css/ionicons.min.css HTTP/1.1" 404 1801
2018-04-13 20:02:37 [basehttp WARNING] "GET /static/ionicons/css/ionicons.min.css HTTP/1.1" 404 1801
2018-04-13 20:02:45 [basehttp INFO] "GET /users/login-log/ HTTP/1.1" 200 13582
2018-04-13 20:02:45 [basehttp INFO] "GET /static/css/plugins/datepicker/datepicker3.css HTTP/1.1" 200 33679
2018-04-13 20:02:45 [basehttp WARNING] "GET /static/ionicons/css/ionicons.min.css HTTP/1.1" 404 1801
2018-04-13 20:02:45 [basehttp INFO] "GET /static/js/plugins/datepicker/bootstrap-datepicker.js HTTP/1.1" 200 46821
2018-04-13 20:02:45 [basehttp WARNING] "GET /static/ionicons/css/ionicons.min.css HTTP/1.1" 404 1801
2018-04-13 20:02:46 [basehttp INFO] "GET /users/user-group HTTP/1.1" 200 14444
2018-04-13 20:02:46 [basehttp WARNING] "GET /static/ionicons/css/ionicons.min.css HTTP/1.1" 404 1801
2018-04-13 20:02:46 [basehttp WARNING] "GET /static/ionicons/css/ionicons.min.css HTTP/1.1" 404 1801
2018-04-13 20:02:46 [basehttp INFO] "GET /api/users/v1/groups/?_=1523620966446 HTTP/1.1" 200 219
2018-04-13 20:02:48 [basehttp INFO] "GET /navis/navi/ HTTP/1.1" 200 15813
2018-04-13 20:02:48 [basehttp WARNING] "GET /static/ionicons/css/ionicons.min.css HTTP/1.1" 404 1801
2018-04-13 20:02:48 [basehttp WARNING] "GET /static/ionicons/css/ionicons.min.css HTTP/1.1" 404 1801
2018-04-13 20:02:48 [basehttp INFO] "GET /api/navis/v1/navi/?_=1523620968380 HTTP/1.1" 200 2
2018-04-13 20:02:49 [basehttp INFO] "GET /navis/navi/create/ HTTP/1.1" 200 10858
2018-04-13 20:02:49 [basehttp WARNING] "GET /static/ionicons/css/ionicons.min.css HTTP/1.1" 404 1801
2018-04-13 20:02:49 [basehttp WARNING] "GET /static/ionicons/css/ionicons.min.css HTTP/1.1" 404 1801
2018-04-13 20:03:25 [basehttp INFO] "POST /navis/navi/create/ HTTP/1.1" 302 0
2018-04-13 20:03:25 [basehttp INFO] "GET /navis/navi/ HTTP/1.1" 200 15934
2018-04-13 20:03:25 [basehttp WARNING] "GET /static/ionicons/css/ionicons.min.css HTTP/1.1" 404 1801
2018-04-13 20:03:25 [basehttp WARNING] "GET /static/ionicons/css/ionicons.min.css HTTP/1.1" 404 1801
2018-04-13 20:03:25 [basehttp INFO] "GET /api/navis/v1/navi/?_=1523621005145 HTTP/1.1" 200 330
2018-04-13 20:03:27 [basehttp INFO] "GET / HTTP/1.1" 200 9460
2018-04-13 20:03:27 [basehttp WARNING] "GET /static/ionicons/css/ionicons.min.css HTTP/1.1" 404 1801
2018-04-13 20:03:27 [basehttp INFO] "GET /media/pictures/59e2e9feda2e5.png HTTP/1.1" 200 16230
2018-04-13 20:03:27 [basehttp WARNING] "GET /static/ionicons/css/ionicons.min.css HTTP/1.1" 404 1801
2018-04-13 20:03:32 [basehttp INFO] "GET / HTTP/1.1" 200 9460
2018-04-13 20:03:32 [basehttp WARNING] "GET /static/ionicons/css/ionicons.min.css HTTP/1.1" 404 1801
2018-04-13 20:03:32 [basehttp INFO] "GET /media/pictures/59e2e9feda2e5.png HTTP/1.1" 304 0
2018-04-13 20:03:32 [basehttp WARNING] "GET /static/ionicons/css/ionicons.min.css HTTP/1.1" 404 1801
2018-04-13 20:03:32 [basehttp INFO] "GET /static/img/facio.ico HTTP/1.1" 200 1744
2018-04-13 20:17:29 [basehttp INFO] "GET /navis/navi/ HTTP/1.1" 200 15813
2018-04-13 20:17:29 [basehttp INFO] "GET /static/css/navi.css HTTP/1.1" 304 0
2018-04-13 20:17:29 [basehttp WARNING] "GET /static/ionicons/css/ionicons.min.css HTTP/1.1" 404 1801
2018-04-13 20:17:29 [basehttp WARNING] "GET /static/ionicons/css/ionicons.min.css HTTP/1.1" 404 1801
2018-04-13 20:17:30 [basehttp INFO] "GET /api/navis/v1/navi/?_=1523621849863 HTTP/1.1" 200 330
2018-04-13 20:17:32 [basehttp INFO] "GET /navis/navi/create/ HTTP/1.1" 200 10858
2018-04-13 20:17:32 [basehttp WARNING] "GET /static/ionicons/css/ionicons.min.css HTTP/1.1" 404 1801
2018-04-13 20:17:32 [basehttp WARNING] "GET /static/ionicons/css/ionicons.min.css HTTP/1.1" 404 1801
2018-04-13 20:18:38 [basehttp INFO] "POST /navis/navi/create/ HTTP/1.1" 302 0
2018-04-13 20:18:38 [basehttp INFO] "GET /navis/navi/ HTTP/1.1" 200 15935
2018-04-13 20:18:38 [basehttp WARNING] "GET /static/ionicons/css/ionicons.min.css HTTP/1.1" 404 1801
2018-04-13 20:18:38 [basehttp WARNING] "GET /static/ionicons/css/ionicons.min.css HTTP/1.1" 404 1801
2018-04-13 20:18:38 [basehttp INFO] "GET /api/navis/v1/navi/?_=1523621918455 HTTP/1.1" 200 648
2018-04-13 20:18:41 [basehttp INFO] "GET /navis/navi/ HTTP/1.1" 200 15813
2018-04-13 20:18:41 [basehttp WARNING] "GET /static/ionicons/css/ionicons.min.css HTTP/1.1" 404 1801
2018-04-13 20:18:41 [basehttp WARNING] "GET /static/ionicons/css/ionicons.min.css HTTP/1.1" 404 1801
2018-04-13 20:18:41 [basehttp INFO] "GET /static/img/facio.ico HTTP/1.1" 200 1744
2018-04-13 20:18:41 [basehttp INFO] "GET /api/navis/v1/navi/?_=1523621921595 HTTP/1.1" 200 648
2018-04-13 20:18:42 [basehttp INFO] "GET / HTTP/1.1" 200 9946
2018-04-13 20:18:42 [basehttp WARNING] "GET /static/ionicons/css/ionicons.min.css HTTP/1.1" 404 1801
2018-04-13 20:18:42 [basehttp INFO] "GET /media/pictures/59e2e9feda2e5.png HTTP/1.1" 304 0
2018-04-13 20:18:42 [basehttp INFO] "GET /media/pictures/jenkins.png HTTP/1.1" 200 2510
2018-04-13 20:18:42 [basehttp WARNING] "GET /static/ionicons/css/ionicons.min.css HTTP/1.1" 404 1801
2018-04-13 20:18:46 [basehttp INFO] "GET / HTTP/1.1" 200 9946
2018-04-13 20:18:46 [basehttp WARNING] "GET /static/ionicons/css/ionicons.min.css HTTP/1.1" 404 1801
2018-04-13 20:18:46 [basehttp INFO] "GET /media/pictures/jenkins.png HTTP/1.1" 304 0
2018-04-13 20:18:46 [basehttp INFO] "GET /static/img/facio.ico HTTP/1.1" 200 1744
2018-04-13 20:24:37 [basehttp INFO] "GET / HTTP/1.1" 200 9946
2018-04-13 20:24:37 [basehttp WARNING] "GET /static/ionicons/css/ionicons.min.css HTTP/1.1" 404 1801
2018-04-13 20:24:37 [basehttp INFO] "GET /media/pictures/59e2e9feda2e5.png HTTP/1.1" 304 0
2018-04-13 20:24:37 [basehttp INFO] "GET /media/pictures/jenkins.png HTTP/1.1" 304 0
2018-04-13 20:24:37 [basehttp WARNING] "GET /static/ionicons/css/ionicons.min.css HTTP/1.1" 404 1801
2018-04-13 20:24:40 [basehttp INFO] "GET / HTTP/1.1" 200 9946
2018-04-13 20:24:40 [basehttp WARNING] "GET /static/ionicons/css/ionicons.min.css HTTP/1.1" 404 1801
2018-04-13 20:24:40 [basehttp WARNING] "GET /static/ionicons/css/ionicons.min.css HTTP/1.1" 404 1801
2018-04-13 20:24:40 [basehttp INFO] "GET /static/img/facio.ico HTTP/1.1" 200 1744
2018-04-13 20:24:44 [basehttp INFO] "GET / HTTP/1.1" 200 9946
2018-04-13 20:24:44 [basehttp WARNING] "GET /static/ionicons/css/ionicons.min.css HTTP/1.1" 404 1801
2018-04-13 20:24:44 [basehttp WARNING] "GET /static/ionicons/css/ionicons.min.css HTTP/1.1" 404 1801
2018-04-13 20:24:44 [basehttp INFO] "GET /static/img/facio.ico HTTP/1.1" 200 1744
2018-04-13 20:24:46 [basehttp INFO] "GET /navis/navi/ HTTP/1.1" 200 15813
2018-04-13 20:24:46 [basehttp WARNING] "GET /static/ionicons/css/ionicons.min.css HTTP/1.1" 404 1801
2018-04-13 20:24:46 [basehttp WARNING] "GET /static/ionicons/css/ionicons.min.css HTTP/1.1" 404 1801
2018-04-13 20:24:46 [basehttp INFO] "GET /api/navis/v1/navi/?_=1523622286397 HTTP/1.1" 200 648
2018-04-13 20:24:48 [basehttp INFO] "GET / HTTP/1.1" 200 9946
2018-04-13 20:24:48 [basehttp WARNING] "GET /static/ionicons/css/ionicons.min.css HTTP/1.1" 404 1801
2018-04-13 20:24:48 [basehttp WARNING] "GET /static/ionicons/css/ionicons.min.css HTTP/1.1" 404 1801
2018-04-13 20:25:00 [basehttp INFO] "GET /navis/navi/ HTTP/1.1" 200 15813
2018-04-13 20:25:00 [basehttp WARNING] "GET /static/ionicons/css/ionicons.min.css HTTP/1.1" 404 1801
2018-04-13 20:25:00 [basehttp WARNING] "GET /static/ionicons/css/ionicons.min.css HTTP/1.1" 404 1801
2018-04-13 20:25:01 [basehttp INFO] "GET /api/navis/v1/navi/?_=1523622300851 HTTP/1.1" 200 648
2018-04-13 20:25:03 [basehttp INFO] "GET /navis/navi/e5a2ca15-9733-4e74-bbf9-6c59a83e3092/update HTTP/1.1" 200 11009
2018-04-13 20:25:03 [basehttp WARNING] "GET /static/ionicons/css/ionicons.min.css HTTP/1.1" 404 1801
2018-04-13 20:25:03 [basehttp WARNING] "GET /static/ionicons/css/ionicons.min.css HTTP/1.1" 404 1801
2018-04-13 20:25:10 [basehttp INFO] "POST /navis/navi/e5a2ca15-9733-4e74-bbf9-6c59a83e3092/update HTTP/1.1" 302 0
2018-04-13 20:25:10 [basehttp INFO] "GET /navis/navi/ HTTP/1.1" 200 15935
2018-04-13 20:25:10 [basehttp WARNING] "GET /static/ionicons/css/ionicons.min.css HTTP/1.1" 404 1801
2018-04-13 20:25:10 [basehttp WARNING] "GET /static/ionicons/css/ionicons.min.css HTTP/1.1" 404 1801
2018-04-13 20:25:10 [basehttp INFO] "GET /api/navis/v1/navi/?_=1523622310273 HTTP/1.1" 200 653
2018-04-13 20:25:12 [basehttp INFO] "GET / HTTP/1.1" 200 9954
2018-04-13 20:25:12 [basehttp WARNING] "GET /static/ionicons/css/ionicons.min.css HTTP/1.1" 404 1801
2018-04-13 20:25:12 [basehttp INFO] "GET /media/pictures/jenkins_xBJY6fS.png HTTP/1.1" 200 17066
2018-04-13 20:25:12 [basehttp WARNING] "GET /static/ionicons/css/ionicons.min.css HTTP/1.1" 404 1801
